<?xml version="1.0" ?>
<!-- =================================================================================== -->
<!-- |    This document was autogenerated by xacro from /home/jim/exparm_ws/src/kuka_lra_noetic/kuka_description/urdf/training_table.urdf.xacro | -->
<!-- |    EDITING THIS FILE BY HAND IS NOT RECOMMENDED                                 | -->
<!-- =================================================================================== -->
<!-- <robot name="kuka_kr4r600" xmlns:xacro="http://wiki.ros.org/xacro"> -->
<robot name="kuka_kr4r600" xmlns:body="http://playerstage.sourceforge.net/gazebo/xmlschema/#body" xmlns:controller="http://playerstage.sourceforge.net/gazebo/xmlschema/#controller" xmlns:gazebo="http://playerstage.sourceforge.net/gazebo/xmlschema/#gz" xmlns:geom="http://playerstage.sourceforge.net/gazebo/xmlschema/#geom" xmlns:interface="http://playerstage.sourceforge.net/gazebo/xmlschema/#interface" xmlns:joint="http://playerstage.sourceforge.net/gazebo/xmlschema/#joint" xmlns:model="http://playerstage.sourceforge.net/gazebo/xmlschema/#model" xmlns:physics="http://playerstage.sourceforge.net/gazebo/xmlschema/#physics" xmlns:renderable="http://playerstage.sourceforge.net/gazebo/xmlschema/#renderable" xmlns:rendering="http://playerstage.sourceforge.net/gazebo/xmlschema/#rendering" xmlns:sensor="http://playerstage.sourceforge.net/gazebo/xmlschema/#sensor" xmlns:xi="http://www.w3.org/2001/XInclude">
    <!-- <xacro:arg name="transmission_hw_interface" default="hardware_interface/PositionJointInterface"/> -->
    <!-- <xacro:include filename="$(find kuka_description)/urdf/common.gazebo.xacro" /> -->
    <!-- colours based on RAL values given in "FAQ - Colours of robot and robot
       controller", version "KUKA.Tifs | 2010-01-21 |YM| DefaultColorsRobotAndController.doc",
       downloaded 2015-07-18 from
       http://www.kuka.be/main/cservice/faqs/hardware/DefaultColorsRobotAndController.pdf

       all RAL colours converted using http://www.visual-graphics.de/en/customer-care/ral-colours
  -->
    <!-- Size of square 'camera' box -->
    <!-- <xacro:include filename="$(find kuka_description)/urdf/kuka.transmission.xacro" /> -->
    <!-- <xacro:include filename="$(find kuka_description)/urdf/kuka.gazebo.xacro" /> -->
    <!-- legal values:
     - hardware_interface/PositionJointInterface
     - hardware_interface/VelocityJointInterface
     - hardware_interface/EffortJointInterface
-->
    <!-- <xacro:macro name="kuka_kr4r600" params="prefix"> -->
    <link name="base_link">
        <inertial>
            <mass value="1" />
            <inertia ixx="1.0" ixy="0.0" ixz="0.0" iyy="1.0" iyz="0.0" izz="1.0" />
            <origin xyz="0 0 0" rpy="0 0 0" />
        </inertial>
        <visual>
            <origin rpy="0 0 0" xyz="0 0 0" />
            <geometry>
                <mesh filename="package://kuka_kr4_support/meshes/kr4r600/visual/base_link.stl" />
            </geometry>
            <material name="">
                <color rgba="0.5058823529411764 0.47058823529411764 0.38823529411764707 1.0" />
            </material>
        </visual>
        <collision>
            <origin rpy="0 0 0" xyz="0 0 0" />
            <geometry>
                <mesh filename="package://kuka_kr4_support/meshes/kr4r600/collision/base_link.stl" />
            </geometry>
        </collision>
        <inertial>
            <origin rpy="0 0 0" xyz="0 0 0" />
            <mass value="7" />
            <inertia ixx="30160574464.000000" ixy="268355824.000000" ixz="396794944.000000" iyy="49449443328.00000" iyz="74363816.000000" izz="47570612224.000000" />
        </inertial>
    </link>
    <link name="link_1">
        <inertial>
            <mass value="1" />
            <inertia ixx="1.0" ixy="0.0" ixz="0.0" iyy="1.0" iyz="0.0" izz="1.0" />
            <origin xyz="0 0 0" rpy="0 0 0" />
        </inertial>
        <visual>
            <origin rpy="0 0 0" xyz="0 0 0" />
            <geometry>
                <mesh filename="package://kuka_kr4_support/meshes/kr4r600/visual/link_1.stl" />
            </geometry>
            <material name="">
                <color rgba="0.9450980392156862 0.9254901960784314 1.0 1.0" />
            </material>
        </visual>
        <collision>
            <origin rpy="0 0 0" xyz="0 0 0" />
            <geometry>
                <mesh filename="package://kuka_kr4_support/meshes/kr4r600/collision/link_1.stl" />
            </geometry>
        </collision>
        <inertial>
            <origin rpy="0 0 0" xyz="0 0 0" />
            <mass value="5" />
            <inertia ixx="29069639680.000000" ixy="16955148.000000" ixz="-75115704.000000" iyy="18764271616.000000" iyz="180538688.000000" izz="20780234752.000000" />
        </inertial>
    </link>
    <link name="link_2">
        <inertial>
            <mass value="1" />
            <inertia ixx="1.0" ixy="0.0" ixz="0.0" iyy="1.0" iyz="0.0" izz="1.0" />
            <origin xyz="0 0 0" rpy="0 0 0" />
        </inertial>
        <visual>
            <origin rpy="0 0 0" xyz="0 0 0" />
            <geometry>
                <mesh filename="package://kuka_kr4_support/meshes/kr4r600/visual/link_2.stl" />
            </geometry>
            <material name="">
                <color rgba="0.9450980392156862 0.9254901960784314 1.0 1.0" />
            </material>
        </visual>
        <collision>
            <origin rpy="0 0 0" xyz="0 0 0" />
            <geometry>
                <mesh filename="package://kuka_kr4_support/meshes/kr4r600/collision/link_2.stl" />
            </geometry>
        </collision>
        <inertial>
            <origin rpy="0 0 0" xyz="0 0 0" />
            <mass value="6" />
            <inertia ixx="17074209792.000000" ixy="568627456.000000" ixz="-1012415616.000000" iyy="54759739392.000000" iyz="2741744.250000" izz="62598627328.000000" />
        </inertial>
    </link>
    <link name="link_3">
        <inertial>
            <mass value="1" />
            <inertia ixx="1.0" ixy="0.0" ixz="0.0" iyy="1.0" iyz="0.0" izz="1.0" />
            <origin xyz="0 0 0" rpy="0 0 0" />
        </inertial>
        <visual>
            <origin rpy="0 0 0" xyz="0 0 0" />
            <geometry>
                <mesh filename="package://kuka_kr4_support/meshes/kr4r600/visual/link_3.stl" />
            </geometry>
            <material name="">
                <color rgba="0.9450980392156862 0.9254901960784314 1.0 1.0" />
            </material>
        </visual>
        <collision>
            <origin rpy="0 0 0" xyz="0 0 0" />
            <geometry>
                <mesh filename="package://kuka_kr4_support/meshes/kr4r600/collision/link_3.stl" />
            </geometry>
        </collision>
        <inertial>
            <origin rpy="0 0 0" xyz="0 0 0" />
            <mass value="4" />
            <inertia ixx="3538344960.000000" ixy="91869584.000000" ixz="-1087638528.000000" iyy="10409157632.000000" iyz="13806910.000000" izz="10024766464.000000" />
        </inertial>
    </link>
    <link name="link_4">
        <inertial>
            <mass value="1" />
            <inertia ixx="1.0" ixy="0.0" ixz="0.0" iyy="1.0" iyz="0.0" izz="1.0" />
            <origin xyz="0 0 0" rpy="0 0 0" />
        </inertial>
        <visual>
            <origin rpy="0 0 0" xyz="0 0 0" />
            <geometry>
                <mesh filename="package://kuka_kr4_support/meshes/kr4r600/visual/link_4.stl" />
            </geometry>
            <material name="">
                <color rgba="0.9450980392156862 0.9254901960784314 1.0 1.0" />
            </material>
        </visual>
        <collision>
            <origin rpy="0 0 0" xyz="0 0 0" />
            <geometry>
                <mesh filename="package://kuka_kr4_support/meshes/kr4r600/collision/link_4.stl" />
            </geometry>
        </collision>
        <inertial>
            <origin rpy="0 0 0" xyz="0 0 0" />
            <mass value="3" />
            <inertia ixx="2312632576.000000" ixy="-262303920.000000" ixz="26849928.000000" iyy="2560956160.000000" iyz="-46212612.000000" izz="3653170944.000000" />
        </inertial>
    </link>
    <link name="link_5">
        <inertial>
            <mass value="1" />
            <inertia ixx="1.0" ixy="0.0" ixz="0.0" iyy="1.0" iyz="0.0" izz="1.0" />
            <origin xyz="0 0 0" rpy="0 0 0" />
        </inertial>
        <visual>
            <origin rpy="0 0 0" xyz="0 0 0" />
            <geometry>
                <mesh filename="package://kuka_kr4_support/meshes/kr4r600/visual/link_5.stl" />
            </geometry>
            <material name="">
                <color rgba="0.9450980392156862 0.9254901960784314 1.0 1.0" />
            </material>
        </visual>
        <collision>
            <origin rpy="0 0 0" xyz="0 0 0" />
            <geometry>
                <mesh filename="package://kuka_kr4_support/meshes/kr4r600/collision/link_5.stl" />
            </geometry>
        </collision>
        <inertial>
            <origin rpy="0 0 0" xyz="0 0 0" />
            <mass value="1.5" />
            <inertia ixx="474922912.000000" ixy="-5465426.000000" ixz="-131389.812500" iyy=" 642145344.000000" iyz="98441.296875" izz="684424448.000000" />
        </inertial>
    </link>
    <link name="link_6">
        <inertial>
            <mass value="1" />
            <inertia ixx="1.0" ixy="0.0" ixz="0.0" iyy="1.0" iyz="0.0" izz="1.0" />
            <origin xyz="0 0 0" rpy="0 0 0" />
        </inertial>
        <visual>
            <origin rpy="0 0 0" xyz="0 0 0" />
            <geometry>
                <mesh filename="package://kuka_kr4_support/meshes/kr4r600/visual/link_6.stl" />
            </geometry>
            <material name="">
                <color rgba="0.5058823529411764 0.47058823529411764 0.38823529411764707 1.0" />
            </material>
        </visual>
        <collision>
            <origin rpy="0 0 0" xyz="0 0 0" />
            <geometry>
                <mesh filename="package://kuka_kr4_support/meshes/kr4r600/collision/link_6.stl" />
            </geometry>
        </collision>
        <inertial>
            <origin rpy="0 0 0" xyz="0 0 0" />
            <mass value="0.5" />
            <inertia ixx="9503564.000000" ixy="-344.500275" ixz="2999.466064" iyy=" 6104710.000000" iyz="2659.174805" izz="6102781.000000" />
        </inertial>
    </link>
    <!-- This frame corresponds to the $FLANGE coordinate system in KUKA KRC controllers. -->
    <link name="tool0" />
    <!-- Camera -->
    <link name="camera_link">
        <collision>
            <origin rpy="0 0 0" xyz="0 0 0" />
            <geometry>
                <box size="0.05 0.05 0.05" />
            </geometry>
        </collision>
        <visual>
            <origin rpy="0 0 0" xyz="0 0 0" />
            <geometry>
                <box size="0.05 0.05 0.05" />
            </geometry>
            <material name="white" />
        </visual>
        <inertial>
            <mass value="1e-5" />
            <origin rpy="0 0 0" xyz="0 0 0" />
            <inertia ixx="1e-6" ixy="0" ixz="0" iyy="1e-6" iyz="0" izz="1e-6" />
        </inertial>
    </link>
    <!-- Hokuyo Laser -->
    <link name="hokuyo_link">
        <collision>
            <origin rpy="0 0 0" xyz="0 0 0" />
            <geometry>
                <box size="0.05 0.05 0.05" />
            </geometry>
        </collision>
        <visual>
            <origin rpy="0 0 0" xyz="0 0 0" />
            <geometry>
                <box size="0.05 0.05 0.05" />
            </geometry>
        </visual>
        <inertial>
            <mass value="1e-5" />
            <origin rpy="0 0 0" xyz="0 0 0" />
            <inertia ixx="1e-6" ixy="0" ixz="0" iyy="1e-6" iyz="0" izz="1e-6" />
        </inertial>
    </link>
    <joint name="joint_a1" type="revolute">
        <origin rpy="0 0 0" xyz="0 0 0.33" />
        <parent link="base_link" />
        <child link="link_1" />
        <axis xyz="0 0 -1" />
        <limit effort="100" lower="-2.9670597283903604" upper="2.9670597283903604" velocity="9.250245035569947" />
    </joint>
    <joint name="joint_a2" type="revolute">
        <origin rpy="0 0 0" xyz="0 0 0" />
        <parent link="link_1" />
        <child link="link_2" />
        <axis xyz="0 1 0" />
        <limit effort="100" lower="-3.4033920413889427" upper="0.6981317007977318" velocity="9.232791743050003" />
    </joint>
    <joint name="joint_a3" type="revolute">
        <origin rpy="0 0 0" xyz="0.290 0 0" />
        <parent link="link_2" />
        <child link="link_3" />
        <axis xyz="0 1 0" />
        <limit effort="100" lower="-2.007128639793479" upper="2.6179938779914944" velocity="9.389871375729493" />
    </joint>
    <joint name="joint_a4" type="revolute">
        <origin rpy="0 0 0" xyz="0.310 0 0.020" />
        <parent link="link_3" />
        <child link="link_4" />
        <axis xyz="-1 0 0" />
        <limit effort="100" lower="-3.2288591161895095" upper="3.2288591161895095" velocity="10.471975511965978" />
    </joint>
    <joint name="joint_a5" type="revolute">
        <origin rpy="0 0 0" xyz="0 0 0" />
        <parent link="link_4" />
        <child link="link_5" />
        <axis xyz="0 1 0" />
        <limit effort="100" lower="-2.0943951023931953" upper="2.0943951023931953" velocity="10.471975511965978" />
    </joint>
    <joint name="joint_a6" type="revolute">
        <origin rpy="0 0 0" xyz="0.075 0 0" />
        <parent link="link_5" />
        <child link="link_6" />
        <axis xyz="-1 0 0" />
        <limit effort="100" lower="-6.1086523819801535" upper="6.1086523819801535" velocity="13.962634015954636" />
    </joint>
    <joint name="joint_a6-tool0" type="fixed">
        <parent link="link_6" />
        <child link="tool0" />
        <origin rpy="0 1.5707963267948966 0" xyz="0 0 0" />
    </joint>
    <joint name="camera_joint" type="fixed">
        <origin rpy="0 -1.5708 0" xyz="0 0 0.025" />
        <parent link="tool0" />
        <child link="camera_link" />
    </joint>
    <joint name="hokuyo_joint" type="fixed">
        <origin rpy="0 0 0" xyz="0 0.05 0" />
        <parent link="camera_link" />
        <child link="hokuyo_link" />
    </joint>
    <!--   <xacro:kuka_arm_transmission prefix="${prefix}" hw_interface="${transmission_hw_interface}" />
  <xacro:kuka_arm_gazebo prefix="${prefix}" />

 -->
    <!-- ROS base_link to KUKA $ROBROOT coordinate system transform -->
    <!--     <link name="${prefix}base" />
    <joint name="${prefix}base_link-base" type="fixed">
      <origin xyz="0 0 0" rpy="0 0 0"/>
      <parent link="${prefix}base_link"/>
      <child link="${prefix}base"/>
    </joint> -->
    <!-- transmission list -->
    <transmission name="tran1">
        <type>transmission_interface/SimpleTransmission</type>
        <joint name="joint_a1">
            <hardwareInterface>hardware_interface/EffortJointInterface</hardwareInterface>
        </joint>
        <actuator name="motor1">
            <mechanicalReduction>1</mechanicalReduction>
            <hardwareInterface>hardware_interface/EffortJointInterface</hardwareInterface>
        </actuator>
    </transmission>
    <transmission name="tran2">
        <type>transmission_interface/SimpleTransmission</type>
        <joint name="joint_a2">
            <hardwareInterface>hardware_interface/EffortJointInterface</hardwareInterface>
        </joint>
        <actuator name="motor2">
            <mechanicalReduction>1</mechanicalReduction>
            <hardwareInterface>hardware_interface/EffortJointInterface</hardwareInterface>
        </actuator>
    </transmission>
    <transmission name="tran3">
        <type>transmission_interface/SimpleTransmission</type>
        <joint name="joint_a3">
            <hardwareInterface>hardware_interface/EffortJointInterface</hardwareInterface>
        </joint>
        <actuator name="motor3">
            <mechanicalReduction>1</mechanicalReduction>
            <hardwareInterface>hardware_interface/EffortJointInterface</hardwareInterface>
        </actuator>
    </transmission>
    <transmission name="tran4">
        <type>transmission_interface/SimpleTransmission</type>
        <joint name="joint_a4">
            <hardwareInterface>hardware_interface/EffortJointInterface</hardwareInterface>
        </joint>
        <actuator name="motor4">
            <mechanicalReduction>1</mechanicalReduction>
            <hardwareInterface>hardware_interface/EffortJointInterface</hardwareInterface>
        </actuator>
    </transmission>
    <transmission name="tran5">
        <type>transmission_interface/SimpleTransmission</type>
        <joint name="joint_a5">
            <hardwareInterface>hardware_interface/EffortJointInterface</hardwareInterface>
        </joint>
        <actuator name="motor5">
            <mechanicalReduction>1</mechanicalReduction>
            <hardwareInterface>hardware_interface/EffortJointInterface</hardwareInterface>
        </actuator>
    </transmission>
    <transmission name="tran6">
        <type>transmission_interface/SimpleTransmission</type>
        <joint name="joint_a6">
            <hardwareInterface>hardware_interface/EffortJointInterface</hardwareInterface>
        </joint>
        <actuator name="motor6">
            <mechanicalReduction>1</mechanicalReduction>
            <hardwareInterface>hardware_interface/EffortJointInterface</hardwareInterface>
        </actuator>
    </transmission>
    <!-- end of transmission list -->
    <!-- Gazebo-specific link properties -->
    <gazebo reference="base_link">
        <material>Gazebo/White</material>
        <turnGravityOff>true</turnGravityOff>
        <plugin name="gazebo_ros_control">
            <robotNamespace>/</robotNamespace>
        </plugin>
    </gazebo>
    <gazebo reference="link_1">
        <material>Gazebo/White</material>
        <turnGravityOff>true</turnGravityOff>
    </gazebo>
    <gazebo reference="link_2">
        <material>Gazebo/White</material>
        <turnGravityOff>true</turnGravityOff>
    </gazebo>
    <gazebo reference="link_3">
        <material>Gazebo/White</material>
        <turnGravityOff>true</turnGravityOff>
    </gazebo>
    <gazebo reference="link_4">
        <material>Gazebo/White</material>
        <turnGravityOff>true</turnGravityOff>
    </gazebo>
    <gazebo reference="link_5">
        <material>Gazebo/White</material>
        <turnGravityOff>true</turnGravityOff>
    </gazebo>
    <gazebo reference="link_6">
        <material>Gazebo/Black</material>
        <turnGravityOff>true</turnGravityOff>
    </gazebo>
    <!-- ros_control plugin -->
    <gazebo>
        <plugin filename="libgazebo_ros_control.so" name="gazebo_ros_control">
            <robotNamespace>/kuka_kr4r600</robotNamespace>
            <robotSimType>gazebo_ros_control/DefaultRobotHWSim</robotSimType>
        </plugin>
    </gazebo>
    <!-- camera -->
    <gazebo reference="camera_link">
        <sensor name="camera1" type="camera">
            <update_rate>30.0</update_rate>
            <camera name="head">
                <horizontal_fov>1.3962634</horizontal_fov>
                <image>
                    <width>800</width>
                    <height>800</height>
                    <format>R8G8B8</format>
                </image>
                <clip>
                    <near>0.02</near>
                    <far>300</far>
                </clip>
                <noise>
                    <type>gaussian</type>
                    <mean>0.0</mean>
                    <stddev>0.007</stddev>
                </noise>
            </camera>
            <plugin filename="libgazebo_ros_camera.so" name="camera_controller">
                <alwaysOn>true</alwaysOn>
                <updateRate>0.0</updateRate>
                <cameraName>kuka/camera1</cameraName>
                <imageTopicName>image_raw</imageTopicName>
                <cameraInfoTopicName>camera_info</cameraInfoTopicName>
                <frameName>camera_link</frameName>
                <hackBaseline>0.07</hackBaseline>
                <distortionK1>0.0</distortionK1>
                <distortionK2>0.0</distortionK2>
                <distortionK3>0.0</distortionK3>
                <distortionT1>0.0</distortionT1>
                <distortionT2>0.0</distortionT2>
            </plugin>
        </sensor>
    </gazebo>
    <!-- hokuyo -->
    <gazebo reference="hokuyo_link">
        <sensor name="head_hokuyo_sensor" type="gpu_ray">
            <pose>0 0 0 0 0 0</pose>
            <visualize>false</visualize>
            <update_rate>40</update_rate>
            <ray>
                <scan>
                    <horizontal>
                        <samples>720</samples>
                        <resolution>1</resolution>
                        <min_angle>-1.570796</min_angle>
                        <max_angle>1.570796</max_angle>
                    </horizontal>
                </scan>
                <range>
                    <min>0.10</min>
                    <max>30.0</max>
                    <resolution>0.01</resolution>
                </range>
                <noise>
                    <type>gaussian</type>
                    <!-- Noise parameters based on published spec for Hokuyo laser
               achieving "+-30mm" accuracy at range < 10m.  A mean of 0.0m and
               stddev of 0.01m will put 99.7% of samples within 0.03m of the true
               reading. -->
                    <mean>0.0</mean>
                    <stddev>0.01</stddev>
                </noise>
            </ray>
            <plugin filename="libgazebo_ros_gpu_laser.so" name="gazebo_ros_head_hokuyo_controller">
                <topicName>/kuka/laser/scan</topicName>
                <frameName>hokuyo_link</frameName>
            </plugin>
        </sensor>
    </gazebo>
    <link name="world" />
    <!-- tabletop height is .55+.01+.025=.585 -->
    <link name="table_top_link">
        <inertial>
            <mass value="1.0" />
            <origin xyz="0.0 0.0 0.775" rpy="0 0 0" />
            <inertia ixx="1" ixy="0" ixz="0" iyy="1" iyz="0" izz="1" />
        </inertial>
        <visual>
            <origin xyz="0.0 0.0 0.775" />
            <geometry>
                <!-- <box size="${table_width} ${table_depth} ${table_top_thickness}" /> -->
                <cylinder length="0.05" radius="0.6" />
            </geometry>
        </visual>
        <collision>
            <origin xyz="0.0 0.0 0.775" />
            <geometry>
                <cylinder length="0.05" radius="0.6" />
                <!-- <box size="${table_width} ${table_depth} ${table_top_thickness}" /> -->
            </geometry>
        </collision>
    </link>
    <gazebo reference="table_top_link">
        <material>Gazebo/LightWood</material>
        <mu1>50.0</mu1>
        <mu2>50.0</mu2>
        <kp>1000000.0</kp>
        <kd>1.0</kd>
    </gazebo>
    <joint name="leg1_joint" type="fixed">
        <parent link="table_top_link" />
        <origin rpy="0 0 0" xyz="0.3 0.3 0.8" />
        <child link="leg1_link" />
    </joint>
    <link name="leg1_link">
        <inertial>
            <mass value="1.0" />
            <origin xyz="0 0 -0.4" rpy="0 0 0" />
            <inertia ixx="0.1" ixy="0" ixz="0" iyy="0.1" iyz="0" izz="0.01" />
        </inertial>
        <visual>
            <origin rpy="0 0 0" xyz="0.0 0.0 -0.4" />
            <geometry>
                <cylinder length="0.8" radius="0.02" />
            </geometry>
        </visual>
        <collision>
            <origin rpy="0.0 0.0 0.0" xyz="0.0 0.0 -0.4" />
            <geometry>
                <cylinder length="0.8" radius="0.02" />
            </geometry>
        </collision>
    </link>
    <gazebo reference="leg1_link">
        <material>Gazebo/White</material>
        <mu1>1000.0</mu1>
        <mu2>1000.0</mu2>
        <kp>10000000.0</kp>
        <kd>1.0</kd>
        <selfCollide>true</selfCollide>
    </gazebo>
    <joint name="leg2_joint" type="fixed">
        <parent link="table_top_link" />
        <origin rpy="0 0 0" xyz="-0.3 0.3 0.8" />
        <child link="leg2_link" />
    </joint>
    <link name="leg2_link">
        <inertial>
            <mass value="1.0" />
            <origin xyz="0 0 -0.4" rpy="0 0 0" />
            <inertia ixx="0.1" ixy="0" ixz="0" iyy="0.1" iyz="0" izz="0.01" />
        </inertial>
        <visual>
            <origin rpy="0 0 0" xyz="0.0 0.0 -0.4" />
            <geometry>
                <cylinder length="0.8" radius="0.02" />
            </geometry>
        </visual>
        <collision>
            <origin rpy="0.0 0.0 0.0" xyz="0.0 0.0 -0.4" />
            <geometry>
                <cylinder length="0.8" radius="0.02" />
            </geometry>
        </collision>
    </link>
    <gazebo reference="leg2_link">
        <material>Gazebo/White</material>
        <mu1>1000.0</mu1>
        <mu2>1000.0</mu2>
        <kp>10000000.0</kp>
        <kd>1.0</kd>
        <selfCollide>true</selfCollide>
    </gazebo>
    <joint name="leg3_joint" type="fixed">
        <parent link="table_top_link" />
        <origin rpy="0 0 0" xyz="0.3 -0.3 0.8" />
        <child link="leg3_link" />
    </joint>
    <link name="leg3_link">
        <inertial>
            <mass value="1.0" />
            <origin xyz="0 0 -0.4" rpy="0 0 0" />
            <inertia ixx="0.1" ixy="0" ixz="0" iyy="0.1" iyz="0" izz="0.01" />
        </inertial>
        <visual>
            <origin rpy="0 0 0" xyz="0.0 0.0 -0.4" />
            <geometry>
                <cylinder length="0.8" radius="0.02" />
            </geometry>
        </visual>
        <collision>
            <origin rpy="0.0 0.0 0.0" xyz="0.0 0.0 -0.4" />
            <geometry>
                <cylinder length="0.8" radius="0.02" />
            </geometry>
        </collision>
    </link>
    <gazebo reference="leg3_link">
        <material>Gazebo/White</material>
        <mu1>1000.0</mu1>
        <mu2>1000.0</mu2>
        <kp>10000000.0</kp>
        <kd>1.0</kd>
        <selfCollide>true</selfCollide>
    </gazebo>
    <joint name="leg4_joint" type="fixed">
        <parent link="table_top_link" />
        <origin rpy="0 0 0" xyz="-0.3 -0.3 0.8" />
        <child link="leg4_link" />
    </joint>
    <link name="leg4_link">
        <inertial>
            <mass value="1.0" />
            <origin xyz="0 0 -0.4" rpy="0 0 0" />
            <inertia ixx="0.1" ixy="0" ixz="0" iyy="0.1" iyz="0" izz="0.01" />
        </inertial>
        <visual>
            <origin rpy="0 0 0" xyz="0.0 0.0 -0.4" />
            <geometry>
                <cylinder length="0.8" radius="0.02" />
            </geometry>
        </visual>
        <collision>
            <origin rpy="0.0 0.0 0.0" xyz="0.0 0.0 -0.4" />
            <geometry>
                <cylinder length="0.8" radius="0.02" />
            </geometry>
        </collision>
    </link>
    <gazebo reference="leg4_link">
        <material>Gazebo/White</material>
        <mu1>1000.0</mu1>
        <mu2>1000.0</mu2>
        <kp>10000000.0</kp>
        <kd>1.0</kd>
        <selfCollide>true</selfCollide>
    </gazebo>
    <gazebo>
        <canonicalBody>table_top_link</canonicalBody>
    </gazebo>
    <!-- attach the table to the world-->
    <joint name="world_joint" type="fixed">
        <parent link="world" />
        <child link="base_link" />
        <origin rpy="0.0 0.0 0.0" xyz="0.0 0.0 0.8" />
    </joint>
    <!-- attach the robot to the table -->
    <joint name="table_joint" type="fixed">
        <parent link="base_link" />
        <child link="table_top_link" />
        <origin rpy="0 0 0" xyz="0 0.0 -0.8" />
    </joint>
    <!--Add box to the table-->
    <link name="box_link">
        <visual>
            <geometry>
                <box size="0.10 0.10 0.10" />
            </geometry>
        </visual>
        <collision>
            <origin rpy="0 0 0" xyz="0 0 0" />
            <geometry>
                <box size="0.10 0.10 0.10" />
            </geometry>
        </collision>
        <inertial>
            <mass value="0.1" />
            <origin xyz="0 0 0" rpy="0 0 0" />
            <inertia ixx="0.03" iyy="0.03" izz="0.03" ixy="0.0" ixz="0.0" iyz="0.0" />
        </inertial>
    </link>
    <gazebo reference="box_link">
        <material>Gazebo/Red</material>
        <mu1>50.0</mu1>
        <mu2>50.0</mu2>
        <kp>1000000.0</kp>
        <kd>1.0</kd>
    </gazebo>
    <!-- attach the box to the table-->
    <joint name="box_joint" type="fixed">
        <parent link="base_link" />
        <child link="box_link" />
        <origin rpy="0.0 0.0 0.0" xyz="0.5 0.0 0.05" />
    </joint>
</robot>

