<?xml version="1.0" ?>
<!-- =================================================================================== -->
<!-- |    This document was autogenerated by xacro from /home/jimdff/exparm_ws/src/kuka_lra_noetic/kuka_description/urdf/dim_kuka.xacro | -->
<!-- |    EDITING THIS FILE BY HAND IS NOT RECOMMENDED                                 | -->
<!-- =================================================================================== -->
<robot name="kuka_kr4r600" xmlns:body="http://playerstage.sourceforge.net/gazebo/xmlschema/#body" xmlns:controller="http://playerstage.sourceforge.net/gazebo/xmlschema/#controller" xmlns:gazebo="http://playerstage.sourceforge.net/gazebo/xmlschema/#gz" xmlns:geom="http://playerstage.sourceforge.net/gazebo/xmlschema/#geom" xmlns:interface="http://playerstage.sourceforge.net/gazebo/xmlschema/#interface" xmlns:joint="http://playerstage.sourceforge.net/gazebo/xmlschema/#joint" xmlns:model="http://playerstage.sourceforge.net/gazebo/xmlschema/#model" xmlns:physics="http://playerstage.sourceforge.net/gazebo/xmlschema/#physics" xmlns:renderable="http://playerstage.sourceforge.net/gazebo/xmlschema/#renderable" xmlns:rendering="http://playerstage.sourceforge.net/gazebo/xmlschema/#rendering" xmlns:sensor="http://playerstage.sourceforge.net/gazebo/xmlschema/#sensor" xmlns:xi="http://www.w3.org/2001/XInclude">
    <!-- colours based on RAL values given in "FAQ - Colours of robot and robot
       controller", version "KUKA.Tifs | 2010-01-21 |YM| DefaultColorsRobotAndController.doc",
       downloaded 2015-07-18 from
       http://www.kuka.be/main/cservice/faqs/hardware/DefaultColorsRobotAndController.pdf

       all RAL colours converted using http://www.visual-graphics.de/en/customer-care/ral-colours
  -->
    <!-- Size of square 'camera' box -->
    <!-- <xacro:include filename="$(find kuka_description)/urdf/kuka.transmission.xacro" /> -->
    <!-- <xacro:include filename="$(find kuka_description)/urdf/kuka.gazebo.xacro" /> -->
    <!-- <xacro:macro name="kuka_kr4r600" params="prefix"> -->
    <!-- dimitris to ebale na fortonei trapezi arxi -->
    <link name="world" />
    <joint name="camera1_joint" type="fixed">
        <parent link="table_top_link" />
        <child link="camera1_link" />
        <origin rpy="0 0 0" xyz="0.6 0 0.815" />
    </joint>
    <link name="camera1_link">
        <visual>
            <geometry>
                <box size="0.010 0.03 0.03" />
            </geometry>
            <material name="red" />
        </visual>
    </link>
    <joint name="camera1_optical_joint" type="fixed">
        <parent link="camera1_link" />
        <child link="camera1_link_optical" />
        <origin rpy="-1.5707963267948966 0 -1.5707963267948966" xyz="0 0 0" />
    </joint>
    <link name="camera1_link_optical" />
    <gazebo reference="camera1_link">
        <material>Gazebo/Green</material>
        <sensor name="camera1" type="camera">
            <pose>0 0 0 0 0 0</pose>
            <visualize>true</visualize>
            <update_rate>10.0</update_rate>
            <camera>
                <horizontal_fov>1.3962634</horizontal_fov>
                <image>
                    <width>640</width>
                    <height>480</height>
                    <format>R8G8B8</format>
                </image>
                <clip>
                    <near>0.05</near>
                    <far>8.0</far>
                </clip>
            </camera>
            <plugin filename="libgazebo_ros_camera.so" name="camera_controller">
                <frameName>camera_link</frameName>
            </plugin>
        </sensor>
        <plugin name="gazebo_ros_control">
            <robotNamespace>/</robotNamespace>
        </plugin>
    </gazebo>
    <!-- tabletop height is .55+.01+.025=.585 -->
    <link name="table_top_link">
        <inertial>
            <mass value="1.0" />
            <origin xyz="0.0 0.0 0.775" rpy="0 0 0" />
            <inertia ixx="1" ixy="0" ixz="0" iyy="1" iyz="0" izz="1" />
        </inertial>
        <visual>
            <origin xyz="0.0 0.0 0.775" />
            <geometry>
                <!-- <box size="${table_width} ${table_depth} ${table_top_thickness}" /> -->
                <cylinder length="0.05" radius="0.6" />
            </geometry>
        </visual>
        <collision>
            <origin xyz="0.0 0.0 0.775" />
            <geometry>
                <cylinder length="0.05" radius="0.6" />
                <!-- <box size="${table_width} ${table_depth} ${table_top_thickness}" /> -->
            </geometry>
        </collision>
    </link>
    <gazebo reference="table_top_link">
        <material>Gazebo/LightWood</material>
        <mu1>50.0</mu1>
        <mu2>50.0</mu2>
        <kp>1000000.0</kp>
        <kd>1.0</kd>
    </gazebo>
    <joint name="leg1_joint" type="fixed">
        <parent link="table_top_link" />
        <origin rpy="0 0 0" xyz="0.3 0.3 0.8" />
        <child link="leg1_link" />
    </joint>
    <link name="leg1_link">
        <inertial>
            <mass value="1.0" />
            <origin xyz="0 0 -0.4" rpy="0 0 0" />
            <inertia ixx="0.1" ixy="0" ixz="0" iyy="0.1" iyz="0" izz="0.01" />
        </inertial>
        <visual>
            <origin rpy="0 0 0" xyz="0.0 0.0 -0.4" />
            <geometry>
                <cylinder length="0.8" radius="0.02" />
            </geometry>
        </visual>
        <collision>
            <origin rpy="0.0 0.0 0.0" xyz="0.0 0.0 -0.4" />
            <geometry>
                <cylinder length="0.8" radius="0.02" />
            </geometry>
        </collision>
    </link>
    <gazebo reference="leg1_link">
        <material>Gazebo/White</material>
        <mu1>1000.0</mu1>
        <mu2>1000.0</mu2>
        <kp>10000000.0</kp>
        <kd>1.0</kd>
        <selfCollide>true</selfCollide>
    </gazebo>
    <joint name="leg2_joint" type="fixed">
        <parent link="table_top_link" />
        <origin rpy="0 0 0" xyz="-0.3 0.3 0.8" />
        <child link="leg2_link" />
    </joint>
    <link name="leg2_link">
        <inertial>
            <mass value="1.0" />
            <origin xyz="0 0 -0.4" rpy="0 0 0" />
            <inertia ixx="0.1" ixy="0" ixz="0" iyy="0.1" iyz="0" izz="0.01" />
        </inertial>
        <visual>
            <origin rpy="0 0 0" xyz="0.0 0.0 -0.4" />
            <geometry>
                <cylinder length="0.8" radius="0.02" />
            </geometry>
        </visual>
        <collision>
            <origin rpy="0.0 0.0 0.0" xyz="0.0 0.0 -0.4" />
            <geometry>
                <cylinder length="0.8" radius="0.02" />
            </geometry>
        </collision>
    </link>
    <gazebo reference="leg2_link">
        <material>Gazebo/White</material>
        <mu1>1000.0</mu1>
        <mu2>1000.0</mu2>
        <kp>10000000.0</kp>
        <kd>1.0</kd>
        <selfCollide>true</selfCollide>
    </gazebo>
    <joint name="leg3_joint" type="fixed">
        <parent link="table_top_link" />
        <origin rpy="0 0 0" xyz="0.3 -0.3 0.8" />
        <child link="leg3_link" />
    </joint>
    <link name="leg3_link">
        <inertial>
            <mass value="1.0" />
            <origin xyz="0 0 -0.4" rpy="0 0 0" />
            <inertia ixx="0.1" ixy="0" ixz="0" iyy="0.1" iyz="0" izz="0.01" />
        </inertial>
        <visual>
            <origin rpy="0 0 0" xyz="0.0 0.0 -0.4" />
            <geometry>
                <cylinder length="0.8" radius="0.02" />
            </geometry>
        </visual>
        <collision>
            <origin rpy="0.0 0.0 0.0" xyz="0.0 0.0 -0.4" />
            <geometry>
                <cylinder length="0.8" radius="0.02" />
            </geometry>
        </collision>
    </link>
    <gazebo reference="leg3_link">
        <material>Gazebo/White</material>
        <mu1>1000.0</mu1>
        <mu2>1000.0</mu2>
        <kp>10000000.0</kp>
        <kd>1.0</kd>
        <selfCollide>true</selfCollide>
    </gazebo>
    <joint name="leg4_joint" type="fixed">
        <parent link="table_top_link" />
        <origin rpy="0 0 0" xyz="-0.3 -0.3 0.8" />
        <child link="leg4_link" />
    </joint>
    <link name="leg4_link">
        <inertial>
            <mass value="1.0" />
            <origin xyz="0 0 -0.4" rpy="0 0 0" />
            <inertia ixx="0.1" ixy="0" ixz="0" iyy="0.1" iyz="0" izz="0.01" />
        </inertial>
        <visual>
            <origin rpy="0 0 0" xyz="0.0 0.0 -0.4" />
            <geometry>
                <cylinder length="0.8" radius="0.02" />
            </geometry>
        </visual>
        <collision>
            <origin rpy="0.0 0.0 0.0" xyz="0.0 0.0 -0.4" />
            <geometry>
                <cylinder length="0.8" radius="0.02" />
            </geometry>
        </collision>
    </link>
    <gazebo reference="leg4_link">
        <material>Gazebo/White</material>
        <mu1>1000.0</mu1>
        <mu2>1000.0</mu2>
        <kp>10000000.0</kp>
        <kd>1.0</kd>
        <selfCollide>true</selfCollide>
    </gazebo>
    <gazebo>
        <canonicalBody>table_top_link</canonicalBody>
    </gazebo>
    <!--
  <xacro:include filename="$(find kuka_description)/urdf/camera1.xacro"/>
  -->
    <!-- attach the table to the world-->
    <joint name="world_joint" type="fixed">
        <parent link="world" />
        <child link="base_link" />
        <origin rpy="0.0 0.0 0.0" xyz="0.0 0.0 0.8" />
    </joint>
    <!-- attach the robot to the table -->
    <joint name="table_joint" type="fixed">
        <parent link="base_link" />
        <child link="table_top_link" />
        <origin rpy="0 0 0" xyz="-0.5 0.0 -0.8" />
    </joint>
    <!-- dimitris to ebale na fortonei trapezi telos  -->
    <link name="base_link">
        <inertial>
            <mass value="100" />
            <inertia ixx="1.0" ixy="0.0" ixz="0.0" iyy="1.0" iyz="0.0" izz="1.0" />
            <origin xyz="0 0 0" rpy="0 0 0" />
        </inertial>
        <visual>
            <origin rpy="0 0 0" xyz="0 0 0" />
            <geometry>
                <mesh filename="package://kuka_kr4_support/meshes/kr4r600/visual/base_link.stl" />
            </geometry>
            <material name="">
                <color rgba="0.5058823529411764 0.47058823529411764 0.38823529411764707 1.0" />
            </material>
        </visual>
        <collision>
            <origin rpy="0 0 0" xyz="0 0 0" />
            <geometry>
                <mesh filename="package://kuka_kr4_support/meshes/kr4r600/collision/base_link.stl" />
            </geometry>
        </collision>
        <inertial>
            <origin rpy="0 0 0" xyz="0 0 0" />
            <mass value="7" />
            <inertia ixx="30160574464.000000" ixy="268355824.000000" ixz="396794944.000000" iyy="49449443328.00000" iyz="74363816.000000" izz="47570612224.000000" />
        </inertial>
    </link>
    <link name="link_1">
        <inertial>
            <mass value="1" />
            <inertia ixx="1.0" ixy="0.0" ixz="0.0" iyy="1.0" iyz="0.0" izz="1.0" />
            <origin xyz="0 0 0" rpy="0 0 0" />
        </inertial>
        <visual>
            <origin rpy="0 0 0" xyz="0 0 0" />
            <geometry>
                <mesh filename="package://kuka_kr4_support/meshes/kr4r600/visual/link_1.stl" />
            </geometry>
            <material name="">
                <color rgba="0.9450980392156862 0.9254901960784314 1.0 1.0" />
            </material>
        </visual>
        <collision>
            <origin rpy="0 0 0" xyz="0 0 0" />
            <geometry>
                <mesh filename="package://kuka_kr4_support/meshes/kr4r600/collision/link_1.stl" />
            </geometry>
        </collision>
        <inertial>
            <origin rpy="0 0 0" xyz="0 0 0" />
            <mass value="5" />
            <inertia ixx="29069639680.000000" ixy="16955148.000000" ixz="-75115704.000000" iyy="18764271616.000000" iyz="180538688.000000" izz="20780234752.000000" />
        </inertial>
    </link>
    <link name="link_2">
        <inertial>
            <mass value="1" />
            <inertia ixx="1.0" ixy="0.0" ixz="0.0" iyy="1.0" iyz="0.0" izz="1.0" />
            <origin xyz="0 0 0" rpy="0 0 0" />
        </inertial>
        <visual>
            <origin rpy="0 0 0" xyz="0 0 0" />
            <geometry>
                <mesh filename="package://kuka_kr4_support/meshes/kr4r600/visual/link_2.stl" />
            </geometry>
            <material name="">
                <color rgba="0.9450980392156862 0.9254901960784314 1.0 1.0" />
            </material>
        </visual>
        <collision>
            <origin rpy="0 0 0" xyz="0 0 0" />
            <geometry>
                <mesh filename="package://kuka_kr4_support/meshes/kr4r600/collision/link_2.stl" />
            </geometry>
        </collision>
        <inertial>
            <origin rpy="0 0 0" xyz="0 0 0" />
            <mass value="6" />
            <inertia ixx="17074209792.000000" ixy="568627456.000000" ixz="-1012415616.000000" iyy="54759739392.000000" iyz="2741744.250000" izz="62598627328.000000" />
        </inertial>
    </link>
    <link name="link_3">
        <inertial>
            <mass value="1" />
            <inertia ixx="1.0" ixy="0.0" ixz="0.0" iyy="1.0" iyz="0.0" izz="1.0" />
            <origin xyz="0 0 0" rpy="0 0 0" />
        </inertial>
        <visual>
            <origin rpy="0 0 0" xyz="0 0 0" />
            <geometry>
                <mesh filename="package://kuka_kr4_support/meshes/kr4r600/visual/link_3.stl" />
            </geometry>
            <material name="">
                <color rgba="0.9450980392156862 0.9254901960784314 1.0 1.0" />
            </material>
        </visual>
        <collision>
            <origin rpy="0 0 0" xyz="0 0 0" />
            <geometry>
                <mesh filename="package://kuka_kr4_support/meshes/kr4r600/collision/link_3.stl" />
            </geometry>
        </collision>
        <inertial>
            <origin rpy="0 0 0" xyz="0 0 0" />
            <mass value="4" />
            <inertia ixx="3538344960.000000" ixy="91869584.000000" ixz="-1087638528.000000" iyy="10409157632.000000" iyz="13806910.000000" izz="10024766464.000000" />
        </inertial>
    </link>
    <link name="link_4">
        <inertial>
            <mass value="1" />
            <inertia ixx="1.0" ixy="0.0" ixz="0.0" iyy="1.0" iyz="0.0" izz="1.0" />
            <origin xyz="0 0 0" rpy="0 0 0" />
        </inertial>
        <visual>
            <origin rpy="0 0 0" xyz="0 0 0" />
            <geometry>
                <mesh filename="package://kuka_kr4_support/meshes/kr4r600/visual/link_4.stl" />
            </geometry>
            <material name="">
                <color rgba="0.9450980392156862 0.9254901960784314 1.0 1.0" />
            </material>
        </visual>
        <collision>
            <origin rpy="0 0 0" xyz="0 0 0" />
            <geometry>
                <mesh filename="package://kuka_kr4_support/meshes/kr4r600/collision/link_4.stl" />
            </geometry>
        </collision>
        <inertial>
            <origin rpy="0 0 0" xyz="0 0 0" />
            <mass value="3" />
            <inertia ixx="2312632576.000000" ixy="-262303920.000000" ixz="26849928.000000" iyy="2560956160.000000" iyz="-46212612.000000" izz="3653170944.000000" />
        </inertial>
    </link>
    <link name="link_5">
        <inertial>
            <mass value="1" />
            <inertia ixx="1.0" ixy="0.0" ixz="0.0" iyy="1.0" iyz="0.0" izz="1.0" />
            <origin xyz="0 0 0" rpy="0 0 0" />
        </inertial>
        <visual>
            <origin rpy="0 0 0" xyz="0 0 0" />
            <geometry>
                <mesh filename="package://kuka_kr4_support/meshes/kr4r600/visual/link_5.stl" />
            </geometry>
            <material name="">
                <color rgba="0.9450980392156862 0.9254901960784314 1.0 1.0" />
            </material>
        </visual>
        <collision>
            <origin rpy="0 0 0" xyz="0 0 0" />
            <geometry>
                <mesh filename="package://kuka_kr4_support/meshes/kr4r600/collision/link_5.stl" />
            </geometry>
        </collision>
        <inertial>
            <origin rpy="0 0 0" xyz="0 0 0" />
            <mass value="1.5" />
            <inertia ixx="474922912.000000" ixy="-5465426.000000" ixz="-131389.812500" iyy=" 642145344.000000" iyz="98441.296875" izz="684424448.000000" />
        </inertial>
    </link>
    <link name="link_6">
        <inertial>
            <mass value="1" />
            <inertia ixx="1.0" ixy="0.0" ixz="0.0" iyy="1.0" iyz="0.0" izz="1.0" />
            <origin xyz="0 0 0" rpy="0 0 0" />
        </inertial>
        <visual>
            <origin rpy="0 0 0" xyz="0 0 0" />
            <geometry>
                <mesh filename="package://kuka_kr4_support/meshes/kr4r600/visual/link_6.stl" />
            </geometry>
            <material name="">
                <color rgba="0.5058823529411764 0.47058823529411764 0.38823529411764707 1.0" />
            </material>
        </visual>
        <collision>
            <origin rpy="0 0 0" xyz="0 0 0" />
            <geometry>
                <mesh filename="package://kuka_kr4_support/meshes/kr4r600/collision/link_6.stl" />
            </geometry>
        </collision>
        <inertial>
            <origin rpy="0 0 0" xyz="0 0 0" />
            <mass value="0.5" />
            <inertia ixx="9503564.000000" ixy="-344.500275" ixz="2999.466064" iyy=" 6104710.000000" iyz="2659.174805" izz="6102781.000000" />
        </inertial>
    </link>
    <!-- This frame corresponds to the $FLANGE coordinate system in KUKA KRC controllers. -->
    <link name="tool0" />
    <!-- Camera -->
    <link name="camera_link">
        <collision>
            <origin rpy="0 0 0" xyz="0 0 0" />
            <geometry>
                <box size="0.05 0.05 0.01" />
            </geometry>
        </collision>
        <visual>
            <origin rpy="0 0 0" xyz="0 0 0" />
            <geometry>
                <box size="0.01 0.05 0.05" />
            </geometry>
            <material name="white" />
        </visual>
        <inertial>
            <mass value="1e-5" />
            <origin rpy="0 0 0" xyz="0 0 0" />
            <inertia ixx="1e-6" ixy="0" ixz="0" iyy="1e-6" iyz="0" izz="1e-6" />
        </inertial>
    </link>
    <joint name="joint_a1" type="revolute">
        <origin rpy="0 0 0" xyz="0 0 0.33" />
        <parent link="base_link" />
        <child link="link_1" />
        <axis xyz="0 0 -1" />
        <limit effort="100" lower="-2.9670597283903604" upper="2.9670597283903604" velocity="9.250245035569947" />
    </joint>
    <joint name="joint_a2" type="revolute">
        <origin rpy="0 0 0" xyz="0 0 0" />
        <parent link="link_1" />
        <child link="link_2" />
        <axis xyz="0 1 0" />
        <limit effort="100" lower="-3.4033920413889427" upper="0.6981317007977318" velocity="9.232791743050003" />
    </joint>
    <joint name="joint_a3" type="revolute">
        <origin rpy="0 0 0" xyz="0.290 0 0" />
        <parent link="link_2" />
        <child link="link_3" />
        <axis xyz="0 1 0" />
        <limit effort="100" lower="-2.007128639793479" upper="2.6179938779914944" velocity="9.389871375729493" />
    </joint>
    <joint name="joint_a4" type="revolute">
        <origin rpy="0 0 0" xyz="0.310 0 0.020" />
        <parent link="link_3" />
        <child link="link_4" />
        <axis xyz="-1 0 0" />
        <limit effort="100" lower="-3.2288591161895095" upper="3.2288591161895095" velocity="10.471975511965978" />
    </joint>
    <joint name="joint_a5" type="revolute">
        <origin rpy="0 0 0" xyz="0 0 0" />
        <parent link="link_4" />
        <child link="link_5" />
        <axis xyz="0 1 0" />
        <limit effort="100" lower="-2.0943951023931953" upper="2.0943951023931953" velocity="10.471975511965978" />
    </joint>
    <joint name="joint_a6" type="revolute">
        <origin rpy="0 0 0" xyz="0.075 0 0" />
        <parent link="link_5" />
        <child link="link_6" />
        <axis xyz="-1 0 0" />
        <limit effort="100" lower="-6.1086523819801535" upper="6.1086523819801535" velocity="13.962634015954636" />
    </joint>
    <joint name="joint_a6-tool0" type="fixed">
        <parent link="link_6" />
        <child link="tool0" />
        <origin rpy="0 1.5707963267948966 0" xyz="0 0 0" />
    </joint>
    <joint name="camera_joint" type="fixed">
        <origin rpy="0 -1.5708 0" xyz="0 0 0.005" />
        <parent link="tool0" />
        <child link="camera_link" />
    </joint>
    <joint name="ee_fixed_joint" type="fixed">
        <parent link="camera_link" />
        <child link="ee_link" />
        <origin rpy="0 0 0" xyz="0 0 0.05" />
    </joint>
    <link name="ee_link">
        <collision>
            <geometry>
                <box size="0.01 0.01 0.01" />
            </geometry>
            <surface>
                <friction>
                    <ode>
                        <mu>10</mu>
                        <mu2>10</mu2>
                    </ode>
                </friction>
            </surface>
            <origin rpy="0 0 0" xyz="-0.01 0 0" />
        </collision>
        <inertial>
            <mass value="0.1" />
            <origin xyz="0 0 0" rpy="0 0 0" />
            <inertia ixx="0.03" iyy="0.03" izz="0.03" ixy="0.0" ixz="0.0" iyz="0.0" />
        </inertial>
    </link>
    <link name="vacuum_gripper">
        <gravity>0</gravity>
        <visual>
            <origin rpy="0 0 0" xyz="0 0 0" />
            <geometry>
                <cylinder length="0.01" radius="0.005" />
            </geometry>
            <material name="white">
                <color rgba="0 0 0 0" />
            </material>
        </visual>
        <inertial>
            <origin rpy="0 0 0" xyz="0.000000 0.000000 0.000000" />
            <mass value="0.0001" />
            <inertia ixx="1e-08" ixy="0" ixz="0" iyy="1e-08" iyz="0" izz="1e-08" />
        </inertial>
    </link>
    <joint name="gripper_joint" type="revolute">
        <axis xyz="1 0 0" />
        <parent link="ee_link" />
        <child link="vacuum_gripper" />
        <origin rpy="0 1.5708 0" xyz="0.01 0.0125 0" />
        <limit effort="50" lower="0" upper="0" velocity="50" />
        <dynamics damping="0.0" friction="10" />
    </joint>
    <gazebo>
        <plugin filename="libgazebo_ros_vacuum_gripper.so" name="gazebo_ros_vacuum_gripper">
            <robotNamespace>/</robotNamespace>
            <bodyName>vacuum_gripper</bodyName>
            <topicName>grasping</topicName>
            <maxForce>50</maxForce>
            <maxDistance>0.05</maxDistance>
            <minDistance>0.01</minDistance>
        </plugin>
    </gazebo>
    <link name="vacuum_gripper1">
        <gravity>0</gravity>
        <visual>
            <origin rpy="0 0 0" xyz="0 0 0" />
            <geometry>
                <cylinder length="0.01" radius="0.005" />
            </geometry>
            <material name="white">
                <color rgba="0 0 0 0" />
            </material>
        </visual>
        <inertial>
            <origin rpy="0 0 0" xyz="0.000000 0.000000 0.000000" />
            <mass value="0.0001" />
            <inertia ixx="1e-08" ixy="0" ixz="0" iyy="1e-08" iyz="0" izz="1e-08" />
        </inertial>
    </link>
    <joint name="gripper_joint1" type="revolute">
        <axis xyz="1 0 0" />
        <parent link="ee_link" />
        <child link="vacuum_gripper1" />
        <origin rpy="0 1.5708 0" xyz="0.01 -0.0125 0" />
        <limit effort="50" lower="0" upper="0" velocity="50" />
        <dynamics damping="0.0" friction="10" />
    </joint>
    <gazebo>
        <plugin filename="libgazebo_ros_vacuum_gripper.so" name="gazebo_ros_vacuum_gripper1">
            <robotNamespace>/</robotNamespace>
            <bodyName>vacuum_gripper1</bodyName>
            <topicName>grasping1</topicName>
            <maxForce>50</maxForce>
            <maxDistance>0.05</maxDistance>
            <minDistance>0.01</minDistance>
        </plugin>
    </gazebo>
    <link name="vacuum_gripper2">
        <gravity>0</gravity>
        <visual>
            <origin rpy="0 0 0" xyz="0 0 0" />
            <geometry>
                <cylinder length="0.01" radius="0.005" />
            </geometry>
            <material name="white">
                <color rgba="0 0 0 0" />
            </material>
        </visual>
        <inertial>
            <origin rpy="0 0 0" xyz="0.000000 0.000000 0.000000" />
            <mass value="0.0001" />
            <inertia ixx="1e-08" ixy="0" ixz="0" iyy="1e-08" iyz="0" izz="1e-08" />
        </inertial>
    </link>
    <joint name="gripper_joint2" type="revolute">
        <axis xyz="1 0 0" />
        <parent link="ee_link" />
        <child link="vacuum_gripper2" />
        <origin rpy="0 1.5708 0" xyz="0.01 0 0.0125" />
        <limit effort="50" lower="0" upper="0" velocity="50" />
        <dynamics damping="0.0" friction="10" />
    </joint>
    <gazebo>
        <plugin filename="libgazebo_ros_vacuum_gripper.so" name="gazebo_ros_vacuum_gripper2">
            <robotNamespace>/</robotNamespace>
            <bodyName>vacuum_gripper2</bodyName>
            <topicName>grasping2</topicName>
            <maxForce>50</maxForce>
            <maxDistance>0.05</maxDistance>
            <minDistance>0.01</minDistance>
        </plugin>
    </gazebo>
    <link name="vacuum_gripper3">
        <gravity>0</gravity>
        <visual>
            <origin rpy="0 0 0" xyz="0 0 0" />
            <geometry>
                <cylinder length="0.01" radius="0.005" />
            </geometry>
            <material name="white">
                <color rgba="0 0 0 0" />
            </material>
        </visual>
        <inertial>
            <origin rpy="0 0 0" xyz="0.000000 0.000000 0.000000" />
            <mass value="0.0001" />
            <inertia ixx="1e-08" ixy="0" ixz="0" iyy="1e-08" iyz="0" izz="1e-08" />
        </inertial>
    </link>
    <joint name="gripper_joint3" type="revolute">
        <axis xyz="1 0 0" />
        <parent link="ee_link" />
        <child link="vacuum_gripper3" />
        <origin rpy="0 1.5708 0" xyz="0.01 0 -0.0125" />
        <limit effort="50" lower="0" upper="0" velocity="50" />
        <dynamics damping="0.0" friction="10" />
    </joint>
    <gazebo>
        <plugin filename="libgazebo_ros_vacuum_gripper.so" name="gazebo_ros_vacuum_gripper3">
            <robotNamespace>/</robotNamespace>
            <bodyName>vacuum_gripper3</bodyName>
            <topicName>grasping2</topicName>
            <maxForce>50</maxForce>
            <maxDistance>0.05</maxDistance>
            <minDistance>0.01</minDistance>
        </plugin>
    </gazebo>
    <link name="vacuum_gripper4">
        <gravity>0</gravity>
        <visual>
            <origin rpy="0 0 0" xyz="0 0 0" />
            <geometry>
                <cylinder length="0.01" radius="0.005" />
            </geometry>
            <material name="white">
                <color rgba="0 0 0 0" />
            </material>
        </visual>
        <inertial>
            <origin rpy="0 0 0" xyz="0.000000 0.000000 0.000000" />
            <mass value="0.0001" />
            <inertia ixx="1e-08" ixy="0" ixz="0" iyy="1e-08" iyz="0" izz="1e-08" />
        </inertial>
    </link>
    <joint name="gripper_joint4" type="revolute">
        <axis xyz="1 0 0" />
        <parent link="ee_link" />
        <child link="vacuum_gripper4" />
        <origin rpy="0 1.5708 0" xyz="0.01 0 0" />
        <limit effort="50" lower="0" upper="0" velocity="50" />
        <dynamics damping="0.0" friction="10" />
    </joint>
    <gazebo>
        <plugin filename="libgazebo_ros_vacuum_gripper.so" name="gazebo_ros_vacuum_gripper4">
            <robotNamespace>/</robotNamespace>
            <bodyName>vacuum_gripper4</bodyName>
            <topicName>grasping4</topicName>
            <maxForce>50</maxForce>
            <maxDistance>0.05</maxDistance>
            <minDistance>0.01</minDistance>
        </plugin>
    </gazebo>
    <link name="vacuum_gripper5">
        <gravity>0</gravity>
        <visual>
            <origin rpy="0 0 0" xyz="0 0 0" />
            <geometry>
                <cylinder length="0.01" radius="0.005" />
            </geometry>
            <material name="white">
                <color rgba="0 0 0 0" />
            </material>
        </visual>
        <inertial>
            <origin rpy="0 0 0" xyz="0.000000 0.000000 0.000000" />
            <mass value="0.0001" />
            <inertia ixx="1e-08" ixy="0" ixz="0" iyy="1e-08" iyz="0" izz="1e-08" />
        </inertial>
    </link>
    <joint name="gripper_joint5" type="revolute">
        <axis xyz="1 0 0" />
        <parent link="ee_link" />
        <child link="vacuum_gripper5" />
        <origin rpy="0 1.5708 0" xyz="0.01 0.0125 0.0125" />
        <limit effort="50" lower="0" upper="0" velocity="50" />
        <dynamics damping="0.0" friction="10" />
    </joint>
    <gazebo>
        <plugin filename="libgazebo_ros_vacuum_gripper.so" name="gazebo_ros_vacuum_gripper">
            <robotNamespace>/</robotNamespace>
            <bodyName>vacuum_gripper5</bodyName>
            <topicName>grasping5</topicName>
            <maxForce>50</maxForce>
            <maxDistance>0.05</maxDistance>
            <minDistance>0.01</minDistance>
        </plugin>
    </gazebo>
    <link name="vacuum_gripper6">
        <gravity>0</gravity>
        <visual>
            <origin rpy="0 0 0" xyz="0 0 0" />
            <geometry>
                <cylinder length="0.01" radius="0.005" />
            </geometry>
            <material name="white">
                <color rgba="0 0 0 0" />
            </material>
        </visual>
        <inertial>
            <origin rpy="0 0 0" xyz="0.000000 0.000000 0.000000" />
            <mass value="0.0001" />
            <inertia ixx="1e-08" ixy="0" ixz="0" iyy="1e-08" iyz="0" izz="1e-08" />
        </inertial>
    </link>
    <joint name="gripper_joint6" type="revolute">
        <axis xyz="1 0 0" />
        <parent link="ee_link" />
        <child link="vacuum_gripper6" />
        <origin rpy="0 1.5708 0" xyz="0.01 -0.0125 0.0125" />
        <limit effort="50" lower="0" upper="0" velocity="50" />
        <dynamics damping="0.0" friction="10" />
    </joint>
    <gazebo>
        <plugin filename="libgazebo_ros_vacuum_gripper.so" name="gazebo_ros_vacuum_gripper1">
            <robotNamespace>/</robotNamespace>
            <bodyName>vacuum_gripper6</bodyName>
            <topicName>grasping6</topicName>
            <maxForce>50</maxForce>
            <maxDistance>0.05</maxDistance>
            <minDistance>0.01</minDistance>
        </plugin>
    </gazebo>
    <link name="vacuum_gripper7">
        <gravity>0</gravity>
        <visual>
            <origin rpy="0 0 0" xyz="0 0 0" />
            <geometry>
                <cylinder length="0.01" radius="0.005" />
            </geometry>
            <material name="white">
                <color rgba="0 0 0 0" />
            </material>
        </visual>
        <inertial>
            <origin rpy="0 0 0" xyz="0.000000 0.000000 0.000000" />
            <mass value="0.0001" />
            <inertia ixx="1e-08" ixy="0" ixz="0" iyy="1e-08" iyz="0" izz="1e-08" />
        </inertial>
    </link>
    <joint name="gripper_joint7" type="revolute">
        <axis xyz="1 0 0" />
        <parent link="ee_link" />
        <child link="vacuum_gripper7" />
        <origin rpy="0 1.5708 0" xyz="0.01 0.0125 -0.0125" />
        <limit effort="50" lower="0" upper="0" velocity="50" />
        <dynamics damping="0.0" friction="10" />
    </joint>
    <gazebo>
        <plugin filename="libgazebo_ros_vacuum_gripper.so" name="gazebo_ros_vacuum_gripper7">
            <robotNamespace>/</robotNamespace>
            <bodyName>vacuum_gripper7</bodyName>
            <topicName>grasping7</topicName>
            <maxForce>50</maxForce>
            <maxDistance>0.05</maxDistance>
            <minDistance>0.01</minDistance>
        </plugin>
    </gazebo>
    <link name="vacuum_gripper8">
        <gravity>0</gravity>
        <visual>
            <origin rpy="0 0 0" xyz="0 0 0" />
            <geometry>
                <cylinder length="0.01" radius="0.005" />
            </geometry>
            <material name="white">
                <color rgba="0 0 0 0" />
            </material>
        </visual>
        <inertial>
            <origin rpy="0 0 0" xyz="0.000000 0.000000 0.000000" />
            <mass value="0.0001" />
            <inertia ixx="1e-08" ixy="0" ixz="0" iyy="1e-08" iyz="0" izz="1e-08" />
        </inertial>
    </link>
    <joint name="gripper_joint8" type="revolute">
        <axis xyz="1 0 0" />
        <parent link="ee_link" />
        <child link="vacuum_gripper8" />
        <origin rpy="0 1.5708 0" xyz="0.01 -0.0125 -0.0125" />
        <limit effort="50" lower="0" upper="0" velocity="50" />
        <dynamics damping="0.0" friction="10" />
    </joint>
    <gazebo>
        <plugin filename="libgazebo_ros_vacuum_gripper.so" name="gazebo_ros_vacuum_gripper8">
            <robotNamespace>/</robotNamespace>
            <bodyName>vacuum_gripper8</bodyName>
            <topicName>grasping8</topicName>
            <maxForce>50</maxForce>
            <maxDistance>0.05</maxDistance>
            <minDistance>0.01</minDistance>
        </plugin>
    </gazebo>
    <transmission name="link_1_trans">
        <type>transmission_interface/SimpleTransmission</type>
        <joint name="joint_a1">
            <hardwareInterface>hardware_interface/PositionJointInterface</hardwareInterface>
        </joint>
        <actuator name="link_1_motor">
            <hardwareInterface>hardware_interface/PositionJointInterface</hardwareInterface>
            <mechanicalReduction>1</mechanicalReduction>
        </actuator>
    </transmission>
    <transmission name="link_2_trans">
        <type>transmission_interface/SimpleTransmission</type>
        <joint name="joint_a2">
            <hardwareInterface>hardware_interface/PositionJointInterface</hardwareInterface>
        </joint>
        <actuator name="link_2_motor">
            <hardwareInterface>hardware_interface/PositionJointInterface</hardwareInterface>
            <mechanicalReduction>1</mechanicalReduction>
        </actuator>
    </transmission>
    <transmission name="link_3_trans">
        <type>transmission_interface/SimpleTransmission</type>
        <joint name="joint_a3">
            <hardwareInterface>hardware_interface/PositionJointInterface</hardwareInterface>
        </joint>
        <actuator name="link_3_motor">
            <hardwareInterface>hardware_interface/PositionJointInterface</hardwareInterface>
            <mechanicalReduction>1</mechanicalReduction>
        </actuator>
    </transmission>
    <transmission name="link_4_trans">
        <type>transmission_interface/SimpleTransmission</type>
        <joint name="joint_a4">
            <hardwareInterface>hardware_interface/PositionJointInterface</hardwareInterface>
        </joint>
        <actuator name="link_4_motor">
            <hardwareInterface>hardware_interface/PositionJointInterface</hardwareInterface>
            <mechanicalReduction>1</mechanicalReduction>
        </actuator>
    </transmission>
    <transmission name="link_5_trans">
        <type>transmission_interface/SimpleTransmission</type>
        <joint name="joint_a5">
            <hardwareInterface>hardware_interface/PositionJointInterface</hardwareInterface>
        </joint>
        <actuator name="link_5_motor">
            <hardwareInterface>hardware_interface/PositionJointInterface</hardwareInterface>
            <mechanicalReduction>1</mechanicalReduction>
        </actuator>
    </transmission>
    <transmission name="link_6_trans">
        <type>transmission_interface/SimpleTransmission</type>
        <joint name="joint_a6">
            <hardwareInterface>hardware_interface/PositionJointInterface</hardwareInterface>
        </joint>
        <actuator name="link_6_motor">
            <hardwareInterface>hardware_interface/PositionJointInterface</hardwareInterface>
            <mechanicalReduction>1</mechanicalReduction>
        </actuator>
    </transmission>
    <gazebo>
        <plugin filename="libgazebo_ros_control.so" name="control">
            <robotNamespace>/</robotNamespace>
        </plugin>
    </gazebo>
    <gazebo reference="link_1">
        <selfCollide>true</selfCollide>
    </gazebo>
    <gazebo reference="link_2">
        <selfCollide>true</selfCollide>
    </gazebo>
    <gazebo reference="link_3">
        <selfCollide>true</selfCollide>
    </gazebo>
    <gazebo reference="link_4">
        <selfCollide>true</selfCollide>
    </gazebo>
    <gazebo reference="link_5">
        <selfCollide>true</selfCollide>
    </gazebo>
    <gazebo reference="link_6">
        <selfCollide>true</selfCollide>
    </gazebo>
    <!--   <xacro:kuka_arm_transmission prefix="${prefix}" hw_interface="${transmission_hw_interface}" />
  <xacro:kuka_arm_gazebo prefix="${prefix}" />

 -->
    <!-- ROS base_link to KUKA $ROBROOT coordinate system transform -->
    <!--     <link name="${prefix}base" />
    <joint name="${prefix}base_link-base" type="fixed">
      <origin xyz="0 0 0" rpy="0 0 0"/>
      <parent link="${prefix}base_link"/>
      <child link="${prefix}base"/>
    </joint> -->
    <transmission name="trans_gripper_joint">
        <type>transmission_interface/SimpleTransmission</type>
        <joint name="gripper_joint">
            <hardwareInterface>hardware_interface/EffortJointInterface</hardwareInterface>
        </joint>
        <actuator name="gripper_joint_motor">
            <hardwareInterface>hardware_interface/EffortJointInterface</hardwareInterface>
            <mechanicalReduction>1</mechanicalReduction>
        </actuator>
    </transmission>
    <transmission name="trans_gripper_joint1">
        <type>transmission_interface/SimpleTransmission</type>
        <joint name="gripper_joint1">
            <hardwareInterface>hardware_interface/EffortJointInterface</hardwareInterface>
        </joint>
        <actuator name="gripper_joint1_motor">
            <hardwareInterface>hardware_interface/EffortJointInterface</hardwareInterface>
            <mechanicalReduction>1</mechanicalReduction>
        </actuator>
    </transmission>
    <transmission name="trans_gripper_joint2">
        <type>transmission_interface/SimpleTransmission</type>
        <joint name="gripper_joint2">
            <hardwareInterface>hardware_interface/EffortJointInterface</hardwareInterface>
        </joint>
        <actuator name="gripper_joint2_motor">
            <hardwareInterface>hardware_interface/EffortJointInterface</hardwareInterface>
            <mechanicalReduction>1</mechanicalReduction>
        </actuator>
    </transmission>
    <transmission name="trans_gripper_joint3">
        <type>transmission_interface/SimpleTransmission</type>
        <joint name="gripper_joint3">
            <hardwareInterface>hardware_interface/EffortJointInterface</hardwareInterface>
        </joint>
        <actuator name="gripper_joint3_motor">
            <hardwareInterface>hardware_interface/EffortJointInterface</hardwareInterface>
            <mechanicalReduction>1</mechanicalReduction>
        </actuator>
    </transmission>
    <transmission name="trans_gripper_joint4">
        <type>transmission_interface/SimpleTransmission</type>
        <joint name="gripper_joint4">
            <hardwareInterface>hardware_interface/EffortJointInterface</hardwareInterface>
        </joint>
        <actuator name="gripper_joint4_motor">
            <hardwareInterface>hardware_interface/EffortJointInterface</hardwareInterface>
            <mechanicalReduction>1</mechanicalReduction>
        </actuator>
    </transmission>
    <transmission name="trans_gripper_joint5">
        <type>transmission_interface/SimpleTransmission</type>
        <joint name="gripper_joint5">
            <hardwareInterface>hardware_interface/EffortJointInterface</hardwareInterface>
        </joint>
        <actuator name="gripper_joint5_motor">
            <hardwareInterface>hardware_interface/EffortJointInterface</hardwareInterface>
            <mechanicalReduction>1</mechanicalReduction>
        </actuator>
    </transmission>
    <transmission name="trans_gripper_joint6">
        <type>transmission_interface/SimpleTransmission</type>
        <joint name="gripper_joint6">
            <hardwareInterface>hardware_interface/EffortJointInterface</hardwareInterface>
        </joint>
        <actuator name="gripper_joint6_motor">
            <hardwareInterface>hardware_interface/EffortJointInterface</hardwareInterface>
            <mechanicalReduction>1</mechanicalReduction>
        </actuator>
    </transmission>
    <transmission name="trans_gripper_joint7">
        <type>transmission_interface/SimpleTransmission</type>
        <joint name="gripper_joint7">
            <hardwareInterface>hardware_interface/EffortJointInterface</hardwareInterface>
        </joint>
        <actuator name="gripper_joint7_motor">
            <hardwareInterface>hardware_interface/EffortJointInterface</hardwareInterface>
            <mechanicalReduction>1</mechanicalReduction>
        </actuator>
    </transmission>
    <transmission name="trans_gripper_joint8">
        <type>transmission_interface/SimpleTransmission</type>
        <joint name="gripper_joint8">
            <hardwareInterface>hardware_interface/EffortJointInterface</hardwareInterface>
        </joint>
        <actuator name="gripper_joint8_motor">
            <hardwareInterface>hardware_interface/EffortJointInterface</hardwareInterface>
            <mechanicalReduction>1</mechanicalReduction>
        </actuator>
    </transmission>
</robot>

