<?xml version="1.0"?>
<robot xmlns:xacro="http://wiki.ros.org/xacro">

    <xacro:macro name="default_inertial" params="mass">
        <inertial>
            <mass value="${mass}" />
            <inertia ixx="1.0" ixy="0.0" ixz="0.0"
                iyy="1.0" iyz="0.0"
                izz="1.0" />
        </inertial>
    </xacro:macro>

  <xacro:include filename="$(find kuka_resources)/urdf/common_materials.xacro"/>
  <!--<xacro:property name="camera_link" value="0.05" /> --><!-- Size of square 'camera' box -->

  <!-- <xacro:include filename="$(find kuka_description)/urdf/kuka.transmission.xacro" /> -->
  <!-- <xacro:include filename="$(find kuka_description)/urdf/kuka.gazebo.xacro" /> -->

  <xacro:macro name="kuka_kr4r600" params="prefix transmission_hw_interface:=hardware_interface/EffortJointInterface">
  <xacro:include filename="$(find kuka_resources)/urdf/common_constants.xacro"/>
  <!-- <xacro:macro name="kuka_kr4r600" params="prefix"> -->
  
  <!-- dimitris to ebale na fortonei trapezi arxi -->
  
  <link name="world" />
  <xacro:include filename="$(find kuka_description)/urdf/table.urdf.xacro"/>
  <xacro:include filename="$(find kuka_description)/urdf/camera1.xacro"/>  



<!-- attach the table to the world-->
  <joint name="world_joint" type="fixed">
    <parent link="world" />
    <child link = "base_link" />
    <origin xyz="0.0 0.0 0.8" rpy="0.0 0.0 0.0" />
  </joint>

<!-- attach the robot to the table -->
  <joint name="table_joint" type="fixed">
    <parent link="base_link"/>
    <child link="table_top_link"/>
    <origin xyz="-0.5 0.0 -0.8" rpy="0 0 0" />
  </joint>
  
  <!-- dimitris to ebale na fortonei trapezi telos  -->  
  
    <link name="${prefix}base_link">
    <xacro:default_inertial mass="100"/>
      <visual>
        <origin xyz="0 0 0" rpy="0 0 0" />
        <geometry>
          <mesh filename="package://kuka_kr4_support/meshes/kr4r600/visual/base_link.stl" />
        </geometry>
        <xacro:material_kuka_pedestal />
      </visual>

      <collision>
        <origin xyz="0 0 0" rpy="0 0 0" />
        <geometry>
          <mesh filename="package://kuka_kr4_support/meshes/kr4r600/collision/base_link.stl" />
        </geometry>
      </collision>

      <inertial>
        <origin xyz="0 0 0" rpy="0 0 0"/>
        <mass value="7"/>
        <inertia
            ixx="30160574464.000000" ixy="268355824.000000" ixz="396794944.000000"
            iyy="49449443328.00000" iyz="74363816.000000"
            izz="47570612224.000000"/>
      </inertial>

    </link>

    <link name="${prefix}link_1">
    <xacro:default_inertial mass="1"/>
      <visual>
        <origin xyz="0 0 0" rpy="0 0 0" />
        <geometry>
          <mesh filename="package://kuka_kr4_support/meshes/kr4r600/visual/link_1.stl" />
        </geometry>
        <xacro:material_kuka_ral_pure_white />
      </visual>

      <collision>
        <origin xyz="0 0 0" rpy="0 0 0" />
        <geometry>
          <mesh filename="package://kuka_kr4_support/meshes/kr4r600/collision/link_1.stl" />
        </geometry>
      </collision>

      <inertial>
        <origin xyz="0 0 0" rpy="0 0 0"/>
        <mass value="5"/>
        <inertia
          ixx="29069639680.000000" ixy="16955148.000000" ixz="-75115704.000000"
          iyy="18764271616.000000" iyz="180538688.000000"
          izz="20780234752.000000"/>
      </inertial>

    </link>

    <link name="${prefix}link_2">
    <xacro:default_inertial mass="1"/>
      <visual>
        <origin xyz="0 0 0" rpy="0 0 0" />
        <geometry>
          <mesh filename="package://kuka_kr4_support/meshes/kr4r600/visual/link_2.stl" />
        </geometry>
        <xacro:material_kuka_ral_pure_white />
      </visual>

      <collision>
        <origin xyz="0 0 0" rpy="0 0 0" />
        <geometry>
          <mesh filename="package://kuka_kr4_support/meshes/kr4r600/collision/link_2.stl" />
        </geometry>
      </collision>

      <inertial>
        <origin xyz="0 0 0" rpy="0 0 0"/>
        <mass value="6"/>
        <inertia
          ixx="17074209792.000000" ixy="568627456.000000" ixz="-1012415616.000000"
          iyy="54759739392.000000" iyz="2741744.250000"
          izz="62598627328.000000"/>
      </inertial>

    </link>

    <link name="${prefix}link_3">
    <xacro:default_inertial mass="1"/>
      <visual>
        <origin xyz="0 0 0" rpy="0 0 0" />
        <geometry>
          <mesh filename="package://kuka_kr4_support/meshes/kr4r600/visual/link_3.stl" />
        </geometry>
        <xacro:material_kuka_ral_pure_white />
      </visual>

      <collision>
        <origin xyz="0 0 0" rpy="0 0 0" />
        <geometry>
          <mesh filename="package://kuka_kr4_support/meshes/kr4r600/collision/link_3.stl" />
        </geometry>
      </collision>

      <inertial>
        <origin xyz="0 0 0" rpy="0 0 0"/>
        <mass value="4"/>
        <inertia
          ixx="3538344960.000000" ixy="91869584.000000" ixz="-1087638528.000000"
          iyy="10409157632.000000" iyz="13806910.000000"
          izz="10024766464.000000"/>
      </inertial>

    </link>

    <link name="${prefix}link_4">
    <xacro:default_inertial mass="1"/>
      <visual>
        <origin xyz="0 0 0" rpy="0 0 0" />
        <geometry>
          <mesh filename="package://kuka_kr4_support/meshes/kr4r600/visual/link_4.stl" />
        </geometry>
        <xacro:material_kuka_ral_pure_white />
      </visual>

      <collision>
        <origin xyz="0 0 0" rpy="0 0 0" />
        <geometry>
          <mesh filename="package://kuka_kr4_support/meshes/kr4r600/collision/link_4.stl" />
        </geometry>
      </collision>

      <inertial>
        <origin xyz="0 0 0" rpy="0 0 0"/>
        <mass value="3"/>
        <inertia
          ixx="2312632576.000000" ixy="-262303920.000000" ixz="26849928.000000"
          iyy="2560956160.000000" iyz="-46212612.000000"
          izz="3653170944.000000"/>
      </inertial>

    </link>

    <link name="${prefix}link_5">
    <xacro:default_inertial mass="1"/>
      <visual>
        <origin xyz="0 0 0" rpy="0 0 0" />
        <geometry>
          <mesh filename="package://kuka_kr4_support/meshes/kr4r600/visual/link_5.stl" />
        </geometry>
        <xacro:material_kuka_ral_pure_white />
      </visual>

      <collision>
        <origin xyz="0 0 0" rpy="0 0 0" />
        <geometry>
          <mesh filename="package://kuka_kr4_support/meshes/kr4r600/collision/link_5.stl" />
        </geometry>
      </collision>

      <inertial>
        <origin xyz="0 0 0" rpy="0 0 0"/>
        <mass value="1.5"/>
        <inertia
          ixx="474922912.000000" ixy="-5465426.000000" ixz="-131389.812500"
          iyy=" 642145344.000000" iyz="98441.296875"
          izz="684424448.000000"/>
      </inertial>

    </link>

    <link name="${prefix}link_6">
    <xacro:default_inertial mass="1"/>
      <visual>
        <origin xyz="0 0 0" rpy="0 0 0" />
        <geometry>
          <mesh filename="package://kuka_kr4_support/meshes/kr4r600/visual/link_6.stl" />
        </geometry>
        <xacro:material_kuka_pedestal />
      </visual>

      <collision>
        <origin xyz="0 0 0" rpy="0 0 0" />
        <geometry>
          <mesh filename="package://kuka_kr4_support/meshes/kr4r600/collision/link_6.stl" />
        </geometry>
      </collision>

      <inertial>
        <origin xyz="0 0 0" rpy="0 0 0"/>
        <mass value="0.5"/>
        <inertia
          ixx="9503564.000000" ixy="-344.500275" ixz="2999.466064"
          iyy=" 6104710.000000" iyz="2659.174805"
          izz="6102781.000000"/>
      </inertial>

    </link>


    <!-- This frame corresponds to the $FLANGE coordinate system in KUKA KRC controllers. -->
    <link name="${prefix}tool0"/>


  <!-- Camera -->
   <!-- <link name="camera_link">
      <collision>
        <origin xyz="0 0 0" rpy="0 0 0"/>
        <geometry>
          <box size="0.05 0.05 0.01"/>
        </geometry>
      </collision>

      <visual>
        <origin xyz="0 0 0" rpy="0 0 0"/>
        <geometry>
          <box size="0.01 0.05 0.05"/>
        </geometry>
        <material name="white"/>
      </visual>

      <inertial>
        <mass value="1e-5" />
        <origin xyz="0 0 0" rpy="0 0 0"/>
        <inertia ixx="1e-6" ixy="0" ixz="0" iyy="1e-6" iyz="0" izz="1e-6" />
      </inertial>
    </link>
     -->


    <joint name="${prefix}joint_a1" type="revolute">
      <origin xyz="0 0 0.33" rpy="0 0 0"/>
      <parent link="${prefix}base_link"/>
      <child link="${prefix}link_1"/>
      <axis xyz="0 0 -1"/>
      <limit lower="${-DEG2RAD * 170}" upper="${DEG2RAD * 170}" effort="100" velocity="${DEG2RAD* 530}"/>
    </joint>

    <joint name="${prefix}joint_a2" type="revolute">
      <origin xyz="0 0 0" rpy="0 0 0"/>
      <parent link="${prefix}link_1"/>
      <child link="${prefix}link_2"/>
      <axis xyz="0 1 0"/>
      <limit lower="${-DEG2RAD * 195}" upper="${DEG2RAD * 40}" effort="100" velocity="${DEG2RAD *529}"/>
    </joint>

    <joint name="${prefix}joint_a3" type="revolute">
      <origin xyz="0.290 0 0" rpy="0 0 0"/>
      <parent link="${prefix}link_2"/>
      <child link="${prefix}link_3"/>
      <axis xyz="0 1 0"/>
      <limit lower="${-DEG2RAD * 115}" upper="${DEG2RAD * 150}" effort="100" velocity="${DEG2RAD * 538}"/>
    </joint>

    <joint name="${prefix}joint_a4" type="revolute">
      <origin xyz="0.310 0 0.020" rpy="0 0 0"/>
      <parent link="${prefix}link_3"/>
      <child link="${prefix}link_4"/>
      <axis xyz="-1 0 0"/>
      <limit lower="${-DEG2RAD * 185}" upper="${DEG2RAD * 185}" effort="100" velocity="${DEG2RAD * 600}"/>
    </joint>

    <joint name="${prefix}joint_a5" type="revolute">
      <origin xyz="0 0 0" rpy="0 0 0"/>
      <parent link="${prefix}link_4"/>
      <child link="${prefix}link_5"/>
      <axis xyz="0 1 0"/>
      <limit lower="${-DEG2RAD * 120}" upper="${DEG2RAD * 120}" effort="100" velocity="${DEG2RAD * 600}"/>
    </joint>

    <joint name="${prefix}joint_a6" type="revolute">
      <origin xyz="0.075 0 0" rpy="0 0 0"/>
      <parent link="${prefix}link_5"/>
      <child link="${prefix}link_6"/>
      <axis xyz="-1 0 0"/>
      <limit lower="${-DEG2RAD * 350}" upper="${DEG2RAD* 350}" effort="100" velocity="${DEG2RAD* 800}"/>
    </joint>
    
    
    <joint name="${prefix}joint_a6-tool0" type="fixed">
      <parent link="${prefix}link_6"/>
      <child link="${prefix}tool0"/>
      <origin xyz="0 0 0" rpy="0 ${DEG2RAD * 90} 0"/>
    </joint>

<!--
    <joint name="camera_joint" type="fixed">
      <origin xyz="0 0 0.005" rpy="0 -1.5708 0"/>
      <parent link="${prefix}tool0"/>
      <child link="camera_link"/>
    </joint>
-->



    <joint name="${prefix}ee_fixed_joint" type="fixed">
      <parent link="${prefix}tool0" />
      <child link = "${prefix}ee_link" />
      <origin xyz="0 0 0.005" rpy="0 -1.5708 0"/>
    </joint>

    <link name="${prefix}ee_link">
     <!-- <collision>
        <geometry>
          <box size="0.01 0.04 0.045"/>    
        </geometry>
        <surface>
          <friction>
            <ode>
              <mu>10</mu>
              <mu2>10</mu2>
            </ode>
          </friction>
        </surface>
        <origin rpy="0 0 0" xyz="0 0 0.005"/>
      </collision> -->
      
      <visual>
        <origin xyz="0 0 0.005" rpy="0 0 0"/>
        <geometry>
          <box size="0.01 0.04 0.045"/>
        </geometry>
        <material name="white"/>
      </visual>      
      <inertial>
        <origin rpy="0 0 0" xyz="0 0 0.005"/>
        <mass value="0.0001"/>
        <inertia ixx="1e-08" ixy="0" ixz="0" iyy="1e-08" iyz="0" izz="1e-08"/>
      </inertial>
    </link>

    <link name="vacuum_gripper">
      <gravity>0</gravity>
      <visual>
        <origin rpy="0 0 0" xyz="0 0 0"/>
        <geometry>
    	  <mesh filename="package://simulation_moveit/meshes/visual/vacuum.stl" scale="0.00038 0.00038 0.00038"/>
        </geometry>
        <material name="white">
          <color rgba="0 0 0 0"/>
        </material>
      </visual>
      <inertial>
        <origin rpy="0 0 0" xyz="0.000000 0.000000 0.000000"/>
        <mass value="0.0001"/>
        <inertia ixx="1e-08" ixy="0" ixz="0" iyy="1e-08" iyz="0" izz="1e-08"/>
      </inertial>
    </link>

    <joint name="gripper_joint" type="revolute">
      <axis xyz="1 0 0" />
      <parent link="ee_link" />
      <child link="vacuum_gripper" />
      <origin rpy="0 1.5708 0" xyz="0.01 0.0125 0" />
      <limit effort="50" velocity="50" lower="0" upper="0" />
      <dynamics damping="0.0" friction="10"/>
    </joint>

  <gazebo>
      <plugin name="gazebo_ros_vacuum_gripper" filename="libgazebo_ros_vacuum_gripper.so">
        <robotNamespace>/kuka_grasp</robotNamespace>
        <bodyName>vacuum_gripper</bodyName>
        <topicName>grasping</topicName>
	      <maxForce>50</maxForce>
        <maxDistance>0.05</maxDistance>
        <minDistance>0.01</minDistance>
      </plugin>
  </gazebo>


    <link name="vacuum_gripper1">
      <gravity>0</gravity>
      <visual>
        <origin rpy="0 0 0" xyz="0 0 0"/>
        <geometry>
    	  <mesh filename="package://simulation_moveit/meshes/visual/vacuum.stl" scale="0.00038 0.00038 0.00038"/>
    	  <!-- <cylinder radius="0.005" length="0.01"/> -->
        </geometry>
        <material name="white">
          <color rgba="0 0 0 0"/>
        </material>
      </visual>
      <inertial>
        <origin rpy="0 0 0" xyz="0.000000 0.000000 0.000000"/>
        <mass value="0.0001"/>
        <inertia ixx="1e-08" ixy="0" ixz="0" iyy="1e-08" iyz="0" izz="1e-08"/>
      </inertial>
    </link>

    <joint name="gripper_joint1" type="revolute">
      <axis xyz="1 0 0" />
      <parent link="ee_link" />
      <child link="vacuum_gripper1" />
      <origin rpy="0 1.5708 0" xyz="0.01 -0.0125 0" />
      <limit effort="50" velocity="50" lower="0" upper="0" />
      <dynamics damping="0.0" friction="10"/>
    </joint>

  <gazebo>
      <plugin name="gazebo_ros_vacuum_gripper1" filename="libgazebo_ros_vacuum_gripper.so">
        <robotNamespace>/kuka_grasp1</robotNamespace>
        <bodyName>vacuum_gripper1</bodyName>
        <topicName>grasping1</topicName>
	      <maxForce>50</maxForce>
        <maxDistance>0.05</maxDistance>
        <minDistance>0.01</minDistance>
      </plugin>
  </gazebo>


    <link name="vacuum_gripper2">
      <gravity>0</gravity>
      <visual>
        <origin rpy="0 0 0" xyz="0 0 0"/>
        <geometry>
    	  <mesh filename="package://simulation_moveit/meshes/visual/vacuum.stl" scale="0.00038 0.00038 0.00038"/>
        </geometry>
        <material name="white">
          <color rgba="0 0 0 0"/>
        </material>
      </visual>
      <inertial>
        <origin rpy="0 0 0" xyz="0.000000 0.000000 0.000000"/>
        <mass value="0.0001"/>
        <inertia ixx="1e-08" ixy="0" ixz="0" iyy="1e-08" iyz="0" izz="1e-08"/>
      </inertial>
    </link>

    <joint name="gripper_joint2" type="revolute">
      <axis xyz="1 0 0" />
      <parent link="ee_link" />
      <child link="vacuum_gripper2" />
      <origin rpy="0 1.5708 0" xyz="0.01 0 0.0125" />
      <limit effort="50" velocity="50" lower="0" upper="0" />
      <dynamics damping="0.0" friction="10"/>
    </joint>

  <gazebo>
      <plugin name="gazebo_ros_vacuum_gripper2" filename="libgazebo_ros_vacuum_gripper.so">
        <robotNamespace>/kuka_grasp2</robotNamespace>
        <bodyName>vacuum_gripper2</bodyName>
        <topicName>grasping2</topicName>
	      <maxForce>50</maxForce>
        <maxDistance>0.05</maxDistance>
        <minDistance>0.01</minDistance>
      </plugin>
  </gazebo>


    <link name="vacuum_gripper3">
      <gravity>0</gravity>
      <visual>
        <origin rpy="0 0 0" xyz="0 0 0"/>
        <geometry>
    	  <mesh filename="package://simulation_moveit/meshes/visual/vacuum.stl" scale="0.00038 0.00038 0.00038"/>
        </geometry>
        <material name="white">
          <color rgba="0 0 0 0"/>
        </material>
      </visual>
      <inertial>
        <origin rpy="0 0 0" xyz="0.000000 0.000000 0.000000"/>
        <mass value="0.0001"/>
        <inertia ixx="1e-08" ixy="0" ixz="0" iyy="1e-08" iyz="0" izz="1e-08"/>
      </inertial>
    </link>

    <joint name="gripper_joint3" type="revolute">
      <axis xyz="1 0 0" />
      <parent link="ee_link" />
      <child link="vacuum_gripper3" />
      <origin rpy="0 1.5708 0" xyz="0.01 0 -0.0125" />
      <limit effort="50" velocity="50" lower="0" upper="0" />
      <dynamics damping="0.0" friction="10"/>
    </joint>

  <gazebo>
      <plugin name="gazebo_ros_vacuum_gripper3" filename="libgazebo_ros_vacuum_gripper.so">
        <robotNamespace>/kuka_grasp3</robotNamespace>
        <bodyName>vacuum_gripper3</bodyName>
        <topicName>grasping3</topicName>
	      <maxForce>50</maxForce>
        <maxDistance>0.05</maxDistance>
        <minDistance>0.01</minDistance>
      </plugin>
  </gazebo>

  <link name="vacuum_gripper4">
    <gravity>0</gravity>
    <visual>
      <origin rpy="0 0 0" xyz="0 0 0"/>
      <geometry>
    	  <mesh filename="package://simulation_moveit/meshes/visual/vacuum.stl" scale="0.00038 0.00038 0.00038"/>
      </geometry>
      <material name="white">
        <color rgba="0 0 0 0"/>
      </material>
    </visual>
    <inertial>
      <origin rpy="0 0 0" xyz="0.000000 0.000000 0.000000"/>
      <mass value="0.0001"/>
      <inertia ixx="1e-08" ixy="0" ixz="0" iyy="1e-08" iyz="0" izz="1e-08"/>
    </inertial>
  </link>

  <joint name="gripper_joint4" type="revolute">
    <axis xyz="1 0 0" />
    <parent link="ee_link" />
    <child link="vacuum_gripper4" />
    <origin rpy="0 1.5708 0" xyz="0.01 0 0" />
    <limit effort="50" velocity="50" lower="0" upper="0" />
    <dynamics damping="0.0" friction="10"/>
  </joint>

  <gazebo>
    <plugin name="gazebo_ros_vacuum_gripper4" filename="libgazebo_ros_vacuum_gripper.so">
      <robotNamespace>/kuka_grasp4</robotNamespace>
      <bodyName>vacuum_gripper4</bodyName>
      <topicName>grasping4</topicName>
      <maxForce>50</maxForce>
      <maxDistance>0.05</maxDistance>
      <minDistance>0.01</minDistance>
    </plugin>
  </gazebo>

  <link name="vacuum_gripper5">
    <gravity>0</gravity>
    <visual>
      <origin rpy="0 0 0" xyz="0 0 0"/>
      <geometry>
    	  <mesh filename="package://simulation_moveit/meshes/visual/vacuum.stl" scale="0.00038 0.00038 0.00038"/>
      </geometry>
      <material name="white">
        <color rgba="0 0 0 0"/>
      </material>
    </visual>
    <inertial>
      <origin rpy="0 0 0" xyz="0.000000 0.000000 0.000000"/>
      <mass value="0.0001"/>
      <inertia ixx="1e-08" ixy="0" ixz="0" iyy="1e-08" iyz="0" izz="1e-08"/>
    </inertial>
  </link>

  <joint name="gripper_joint5" type="revolute">
    <axis xyz="1 0 0" />
    <parent link="ee_link" />
    <child link="vacuum_gripper5" />
    <origin rpy="0 1.5708 0" xyz="0.01 0.0125 0.0125" />
    <limit effort="50" velocity="50" lower="0" upper="0" />
    <dynamics damping="0.0" friction="10"/>
  </joint>

<gazebo>
    <plugin name="gazebo_ros_vacuum_gripper5" filename="libgazebo_ros_vacuum_gripper.so">
      <robotNamespace>/kuka_grasp5</robotNamespace>
      <bodyName>vacuum_gripper5</bodyName>
      <topicName>grasping5</topicName>
      <maxForce>50</maxForce>
      <maxDistance>0.05</maxDistance>
      <minDistance>0.01</minDistance>
    </plugin>
</gazebo>


  <link name="vacuum_gripper6">
    <gravity>0</gravity>
    <visual>
      <origin rpy="0 0 0" xyz="0 0 0"/>
      <geometry>
    	  <mesh filename="package://simulation_moveit/meshes/visual/vacuum.stl" scale="0.00038 0.00038 0.00038"/>
      </geometry>
      <material name="white">
        <color rgba="0 0 0 0"/>
      </material>
    </visual>
    <inertial>
      <origin rpy="0 0 0" xyz="0.000000 0.000000 0.000000"/>
      <mass value="0.0001"/>
      <inertia ixx="1e-08" ixy="0" ixz="0" iyy="1e-08" iyz="0" izz="1e-08"/>
    </inertial>
  </link>

  <joint name="gripper_joint6" type="revolute">
    <axis xyz="1 0 0" />
    <parent link="ee_link" />
    <child link="vacuum_gripper6" />
    <origin rpy="0 1.5708 0" xyz="0.01 -0.0125 0.0125" />
    <limit effort="50" velocity="50" lower="0" upper="0" />
    <dynamics damping="0.0" friction="10"/>
  </joint>

<gazebo>
    <plugin name="gazebo_ros_vacuum_gripper6" filename="libgazebo_ros_vacuum_gripper.so">
      <robotNamespace>/kuka_grasp6</robotNamespace>
      <bodyName>vacuum_gripper6</bodyName>
      <topicName>grasping6</topicName>
      <maxForce>50</maxForce>
      <maxDistance>0.05</maxDistance>
      <minDistance>0.01</minDistance>
    </plugin>
</gazebo>


  <link name="vacuum_gripper7">
    <gravity>0</gravity>
    <visual>
      <origin rpy="0 0 0" xyz="0 0 0"/>
      <geometry>
    	  <mesh filename="package://simulation_moveit/meshes/visual/vacuum.stl" scale="0.00038 0.00038 0.00038"/>
      </geometry>
      <material name="white">
        <color rgba="0 0 0 0"/>
      </material>
    </visual>
    <inertial>
      <origin rpy="0 0 0" xyz="0.000000 0.000000 0.000000"/>
      <mass value="0.0001"/>
      <inertia ixx="1e-08" ixy="0" ixz="0" iyy="1e-08" iyz="0" izz="1e-08"/>
    </inertial>
  </link>

  <joint name="gripper_joint7" type="revolute">
    <axis xyz="1 0 0" />
    <parent link="ee_link" />
    <child link="vacuum_gripper7" />
    <origin rpy="0 1.5708 0" xyz="0.01 0.0125 -0.0125" />
    <limit effort="50" velocity="50" lower="0" upper="0" />
    <dynamics damping="0.0" friction="10"/>
  </joint>

<gazebo>
    <plugin name="gazebo_ros_vacuum_gripper7" filename="libgazebo_ros_vacuum_gripper.so">
      <robotNamespace>/kuka_grasp7</robotNamespace>
      <bodyName>vacuum_gripper7</bodyName>
      <topicName>grasping7</topicName>
	    <maxForce>50</maxForce>
      <maxDistance>0.05</maxDistance>
      <minDistance>0.01</minDistance>
    </plugin>
</gazebo>


  <link name="vacuum_gripper8">
    <gravity>0</gravity>
    <visual>
      <origin rpy="0 0 0" xyz="0 0 0"/>
      <geometry>
    	  <mesh filename="package://simulation_moveit/meshes/visual/vacuum.stl" scale="0.00038 0.00038 0.00038"/>
      </geometry>
      <material name="white">
        <color rgba="0 0 0 0"/>
      </material>
    </visual>
    <inertial>
      <origin rpy="0 0 0" xyz="0.000000 0.000000 0.000000"/>
      <mass value="0.0001"/>
      <inertia ixx="1e-08" ixy="0" ixz="0" iyy="1e-08" iyz="0" izz="1e-08"/>
    </inertial>
  </link>

  <joint name="gripper_joint8" type="revolute">
    <axis xyz="1 0 0" />
    <parent link="ee_link" />
    <child link="vacuum_gripper8" />
    <origin rpy="0 1.5708 0" xyz="0.01 -0.0125 -0.0125" />
    <limit effort="50" velocity="50" lower="0" upper="0" />
    <dynamics damping="0.0" friction="10"/>
  </joint>

<gazebo>
    <plugin name="gazebo_ros_vacuum_gripper8" filename="libgazebo_ros_vacuum_gripper.so">
      <robotNamespace>/kuka_grasp8</robotNamespace>
      <bodyName>vacuum_gripper8</bodyName>
      <topicName>grasping8</topicName>
      <maxForce>50</maxForce>
      <maxDistance>0.05</maxDistance>
      <minDistance>0.01</minDistance>
    </plugin>
</gazebo>




    <transmission name="link_1_trans">
	<type>transmission_interface/SimpleTransmission</type>
	<joint name="joint_a1">
	<hardwareInterface>hardware_interface/PositionJointInterface</hardwareInterface>
	</joint>
	<actuator name="link_1_motor">
	<hardwareInterface>hardware_interface/PositionJointInterface</hardwareInterface>
	<mechanicalReduction>1</mechanicalReduction>
	</actuator>
    </transmission>
    
    <transmission name="link_2_trans">
	<type>transmission_interface/SimpleTransmission</type>
	<joint name="joint_a2">
	<hardwareInterface>hardware_interface/PositionJointInterface</hardwareInterface>
	</joint>
	<actuator name="link_2_motor">
	<hardwareInterface>hardware_interface/PositionJointInterface</hardwareInterface>
	<mechanicalReduction>1</mechanicalReduction>
	</actuator>
    </transmission>
    
    <transmission name="link_3_trans">
	<type>transmission_interface/SimpleTransmission</type>
	<joint name="joint_a3">
	<hardwareInterface>hardware_interface/PositionJointInterface</hardwareInterface>
	</joint>
	<actuator name="link_3_motor">
	<hardwareInterface>hardware_interface/PositionJointInterface</hardwareInterface>
	<mechanicalReduction>1</mechanicalReduction>
	</actuator>
    </transmission>
    
    <transmission name="link_4_trans">
	<type>transmission_interface/SimpleTransmission</type>
	<joint name="joint_a4">
	<hardwareInterface>hardware_interface/PositionJointInterface</hardwareInterface>
	</joint>
	<actuator name="link_4_motor">
	<hardwareInterface>hardware_interface/PositionJointInterface</hardwareInterface>
	<mechanicalReduction>1</mechanicalReduction>
	</actuator>
    </transmission>
    
    <transmission name="link_5_trans">
	<type>transmission_interface/SimpleTransmission</type>
	<joint name="joint_a5">
	<hardwareInterface>hardware_interface/PositionJointInterface</hardwareInterface>
	</joint>
	<actuator name="link_5_motor">
	<hardwareInterface>hardware_interface/PositionJointInterface</hardwareInterface>
	<mechanicalReduction>1</mechanicalReduction>
	</actuator>
    </transmission>
    
    <transmission name="link_6_trans">
	<type>transmission_interface/SimpleTransmission</type>
	<joint name="joint_a6">
	<hardwareInterface>hardware_interface/PositionJointInterface</hardwareInterface>
	</joint>
	<actuator name="link_6_motor">
	<hardwareInterface>hardware_interface/PositionJointInterface</hardwareInterface>
	<mechanicalReduction>1</mechanicalReduction>
	</actuator>
    </transmission>
    
    <gazebo>
	<plugin name="control" filename="libgazebo_ros_control.so">
	<robotNamespace>/</robotNamespace>
	</plugin>
    </gazebo>
    
    <gazebo reference="link_1">
	<selfCollide>true</selfCollide>
    </gazebo>
    
    <gazebo reference="link_2">
	<selfCollide>true</selfCollide>
    </gazebo>
    
    <gazebo reference="link_3">
	<selfCollide>true</selfCollide>
    </gazebo>
    
    <gazebo reference="link_4">
	<selfCollide>true</selfCollide>
    </gazebo>
    
    <gazebo reference="link_5">
	<selfCollide>true</selfCollide>
    </gazebo>
    
    <gazebo reference="link_6">
	<selfCollide>true</selfCollide>
    </gazebo>
    
 <!--   <gazebo>
      <plugin name="gazebo_ros_vacuum_gripper" filename="libgazebo_ros_vacuum_gripper.so">
         <robotNamespace>/</robotNamespace>
         <bodyName>${prefix}link_6</bodyName>
         <topicName>grasping</topicName>
         <maxForce>500</maxForce>
         <maxDistance>0.10</maxDistance>
     <minDistance>0.01</minDistance>
      </plugin>
      </gazebo>
  -->  

<!--   <xacro:kuka_arm_transmission prefix="${prefix}" hw_interface="${transmission_hw_interface}" />
  <xacro:kuka_arm_gazebo prefix="${prefix}" />

 -->
    <!-- ROS base_link to KUKA $ROBROOT coordinate system transform -->
<!--     <link name="${prefix}base" />
    <joint name="${prefix}base_link-base" type="fixed">
      <origin xyz="0 0 0" rpy="0 0 0"/>
      <parent link="${prefix}base_link"/>
      <child link="${prefix}base"/>
    </joint> -->

  </xacro:macro>

</robot>
